Workbook

Sheet 1
A1: GM MORNING POSITION | O1: DATE | P1: 46785 | S1: PAGE-1
A2: COMPARATIVE LOADING PERFORMANCE AS ON | I2: =P1-1 | K2: Avg Progressive LDG per day for the whole Year | N2: LOADING TARGET 2026-27
A3: Commodity | B3: Target per day for Aug-26 | C3: Cuurent Year | F3: Last Year | H3: Diff in AVG | I3: Avg for the whole Month AUG-2025 | J3: Diff in Avg | K3: Current Year from April-2026 | L3: Last Year from April-2025 | M3: Last Year Upto 31st March-2026 | N3: 46143 | P3: WAGONS | R3: LOADING IN MILLION TONNES
C4: No of Rakes | D4: Wagons | E4: Monthly Avg till date | F4: Wagons | G4: Monthly Avg till date | P4: 2025-2026 | Q4: 2026-2027 | R4: 2025-2026 | S4: 2026-2027
A5: CEM | B5: 0 | E5: =LINK!BP3 | F5: =LINK!B32 | G5: =LINK!AI32 | H5: =E5-G5 | I5: =LINK!B61 | J5: =E5-I5 | K5: =LINK!EG3 | L5: =LINK!BP32 | M5: =LINK!C61 | N5: Loading Target 2026-2027 | P5: 2058189 | Q5: 2208615 | S5: 109.47
A6: COAL | B6: 0 | E6: =LINK!BP4 | F6: =LINK!B33 | G6: =LINK!AI33 | H6: =E6-G6 | I6: =LINK!B62 | J6: =E6-I6 | K6: =LINK!EG4 | L6: =LINK!BP33 | M6: =LINK!C62 | N6: Progressive Loading Up To JULY | P6: 666648 | Q6: 677642 | R6: 32.81 | S6: 34.47
A7: CONT | B7: 0 | E7: =LINK!BP5 | F7: =LINK!B34 | G7: =LINK!AI34 | H7: =E7-G7 | I7: =LINK!B63 | J7: =E7-I7 | K7: =LINK!EG5 | L7: =LINK!BP34 | M7: =LINK!C63 | N7: Today's Ldg | P7: =F18 | Q7: =D18 | R7: 0.26 | S7: 0.24
A8: FERT | B8: 0 | E8: =LINK!BP6 | F8: =LINK!B35 | G8: =LINK!AI35 | H8: =E8-G8 | I8: =LINK!B64 | J8: =E8-I8 | K8: =LINK!EG6 | L8: =LINK!BP35 | M8: =LINK!C64 | N8: Current month LDG Till date | P8: =LINK!AI70 | Q8: =LINK!BP27 | R8: 0.26 | S8: 0.24
A9: IMFT | E9: =LINK!BP7 | F9: =LINK!B36 | G9: =LINK!AI36 | H9: =E9-G9 | I9: =LINK!B65 | J9: =E9-I9 | K9: =LINK!EG7 | L9: =LINK!BP36 | M9: =LINK!C65 | N9: DIVISON WISE CUMM LOADING
A10: POL | B10: 0 | E10: =LINK!BP8 | F10: =LINK!B37 | G10: =LINK!AI37 | H10: =E10-G10 | I10: =LINK!B66 | J10: =E10-I10 | K10: =LINK!EG8 | L10: =LINK!BP37 | M10: =LINK!C66 | N10: ADI | P10: =LINK!AI60+LINK!AI61 | Q10: =LINK!CZ20 | R10: 14.32 | S10: 17.59
A11: SALT | B11: 0 | E11: =LINK!BP9 | F11: =LINK!B38 | G11: =LINK!AI38 | H11: =E11-G11 | I11: =LINK!B67 | J11: =E11-I11 | K11: =LINK!EG9 | L11: =LINK!BP38 | M11: =LINK!C67 | N11: BCT | P11: =LINK!AI62 | Q11: =LINK!CZ21 | R11: 0.37 | S11: 0.31
A12: STEEL | B12: 0 | E12: =LINK!BP10 | F12: =LINK!B39 | G12: =LINK!AI39 | H12: =E12-G12 | I12: =LINK!B68 | J12: =E12-I12 | K12: =LINK!EG10 | L12: =LINK!BP39 | M12: =LINK!C68 | N12: BRC | P12: =LINK!AI63 | Q12: =LINK!CZ22 | R12: 4.92 | S12: 2.9
A13: DOC | B13: 0 | E13: =LINK!BP11 | F13: =LINK!B40 | G13: =LINK!AI40 | H13: =E13-G13 | I13: =LINK!B69 | J13: =E13-I13 | K13: =LINK!EG11 | L13: =LINK!BP40 | M13: =LINK!C69 | N13: RJT | P13: =LINK!AI64 | Q13: =LINK!CZ23 | R13: 6.17 | S13: 4.88
A14: FG | B14: 0 | E14: =LINK!BP12 | F14: =LINK!B41 | G14: =LINK!AI41 | H14: =E14-G14 | I14: =LINK!B70 | J14: =E14-I14 | K14: =LINK!EG12 | L14: =LINK!BP41 | M14: =LINK!C70 | N14: BVC | P14: =LINK!AI65 | Q14: =LINK!CZ24 | R14: 2.14 | S14: 4
A15: CHEM | B15: 0 | E15: =LINK!BP13 | F15: =LINK!B42 | G15: =LINK!AI42 | H15: =E15-G15 | I15: =LINK!B71 | J15: =E15-I15 | K15: =LINK!EG13 | L15: =LINK!BP42 | M15: =LINK!C71 | N15: RTM | P15: =LINK!AI66 | Q15: =LINK!CZ25 | R15: 4.12 | S15: 4.72
A16: AUTO | B16: 0 | E16: =LINK!BP14 | F16: =LINK!B43 | G16: =LINK!AI43 | H16: =E16-G16 | I16: =LINK!B72 | J16: =E16-I16 | K16: =LINK!EG14 | L16: =LINK!BP43 | M16: =LINK!C72 | N16: Progressive LDG from April | P16: =LINK!AI67 | Q16: =LINK!CZ27 | R16: =SUM(R10:R15) | S16: =SUM(S10:S15)
A17: OTHERS | B17: 0 | E17: =LINK!BP15 | F17: =LINK!B44 | G17: =LINK!AI44 | H17: =E17-G17 | I17: =LINK!B73 | J17: =E17-I17 | K17: =LINK!EG15 | L17: =LINK!BP44 | M17: =LINK!C73 | N17: To Achieve Target | Q17: =+Q5-Q16 | S17: =+S5-S16
A18: TOTAL | B18: =SUM(B5:B17) | C18: =SUM(C5:C17) | D18: =SUM(D5:D17) | E18: =SUM(E5:E17) | F18: =SUM(F5:F17) | G18: =SUM(G5:G17) | H18: =SUM(H5:H17) | I18: =SUM(I5:I17) | ... M18: =SUM(M5:M17)
A19: DIV | B19: =B3 | C19: Cuurent Year | F19: Last Year | H19: Diff | I19: Avg for the whole Month AUG-2025 | J19: Diff in Avg | K19: Current Year from April-2026 | L19: Last Year from April-2025 | M19: Last Year Upto 31st March-2026 | N19: RAKE LOADING AND THEIR AVG
C20: No of Rakes | D20: Wagons | E20: Monthly Avg till date | F20: Wagons | G20: Monthly Avg till date | N20: STOCK | P20: YDAY LDG | R20: AVG
A21: ADI | B21: 0 | E21: =LINK!BP20 | F21: =LINK!B49 | G21: =LINK!AI49 | H21: =E21-G21 | I21: =LINK!B77 | J21: =E21-I21 | K21: =LINK!EG20 | L21: =LINK!BP49 | M21: =LINK!C77 | N21: JUMBO | R21: =LINK!BP89
A22: GIMB | B22: 0 | E22: =LINK!BP21 | F22: =LINK!B50 | G22: =LINK!AI50 | H22: =E22-G22 | I22: =LINK!B78 | J22: =E22-I22 | K22: =LINK!EG21 | L22: =LINK!BP50 | M22: =LINK!C78 | N22: BOXN | R22: =LINK!BP90
A23: BCT | B23: 0 | E23: =LINK!BP22 | F23: =LINK!B51 | G23: =LINK!AI51 | H23: =E23-G23 | I23: =LINK!B79 | J23: =E23-I23 | K23: =LINK!EG22 | L23: =LINK!BP51 | M23: =LINK!C79 | N23: BTPN | R23: =LINK!BP91
A24: BRC | B24: 0 | E24: =LINK!BP23 | F24: =LINK!B52 | G24: =LINK!AI52 | H24: =E24-G24 | I24: =LINK!B80 | J24: =E24-I24 | K24: =LINK!EG23 | L24: =LINK!BP52 | M24: =LINK!C80 | N24: BTPGN | R24: =LINK!BP92
A25: RJT | B25: 0 | E25: =LINK!BP24 | F25: =LINK!B53 | G25: =LINK!AI53 | H25: =E25-G25 | I25: =LINK!B81 | J25: =E25-I25 | K25: =LINK!EG24 | L25: =LINK!BP53 | M25: =LINK!C81 | N25: CONT | R25: =LINK!BP93
A26: BVP | B26: 0 | E26: =LINK!BP25 | F26: =LINK!B54 | G26: =LINK!AI54 | H26: =E26-G26 | I26: =LINK!B82 | J26: =E26-I26 | K26: =LINK!EG25 | L26: =LINK!BP54 | M26: =LINK!C82 | N26: SHRA | R26: =LINK!BP94
A27: RTM | B27: 0 | E27: =LINK!BP26 | F27: =LINK!B55 | G27: =LINK!AI55 | H27: =E27-G27 | I27: =LINK!B83 | J27: =E27-I27 | K27: =LINK!EG26 | L27: =LINK!BP55 | M27: =LINK!C83 | N27: OTHERS | R27: =LINK!BP95
A28: TOTAL | B28: =SUM(B21:B27) | C28: =SUM(C21:C27) | D28: =SUM(D21:D27) | E28: =SUM(E21:E27) | F28: =SUM(F21:F27) | G28: =SUM(G21:G27) | H28: =SUM(H21:H27) | I28: =SUM(I21:I27) | ... M28: =SUM(M21:M27) | N28: TOTAL RAKES | P28: =SUM(P21:P27) | R28: =SUM(R21:R27)
A29: SILO BALANCE AT PORTS | G29: INDIGENOUS FERT SILO | I29: CONTAINER PENDENCY AT PORTS | N29: Loading Last Year As On | Q29: Last Year Progressive LDG from April-2026
A30: PORTS | B30: FERTILISERS | E30: COAL | F30: GYPSUM | G30: GSFM | I30: PORT | K30: TOTAL | L30: READY | M30: CONCOR | N30: =P1-365 | Q30: =N30+1
B31: DAP | C31: UREA | D31: OTHERS | G31: IFFB | I31: MDCC | J31: SOUTH PORT | N31: =LINK!B100 | P31: =LINK!B101 | Q31: =LINK!B102
A32: MDCC/WPA | B32: =G45 | C32: =G46 | D32: =SUM(G47:G51) | E32: =G54 | G32: IFFG | H32: =G80+G81 | J32: MICT | N32: DOUBLE STACK LDG | Q32: YDAY LONG HAUL & PROG
A33: KDLP/KPRK | B33: =G56 | C33: =G57 | D33: =SUM(G58:G64) | E33: =G67 | G33: GSFS | I33: Total | K33: =+K32+K31 | L33: =L31+L32 | M33: =M31+M32 | N33: STN | O33: YDAY | P33: PROG | Q33: MDCC | S33: =+R33
A34: IFFG | G34: GNVS | I34: PPSP | N34: MDCC | P34: =+O34 | Q34: CECC | S34: =+R34
A35: TUNA PORT | B35: =G69 | C35: =G71 | D35: =G70 | E35: =SUM(G74:G76) | G35: KBCS | I35: OUTSATNDING INDENTS | N35: PPSP | P35: =+O35 | Q35: BILD | S35: =+R35
A36: NAVLAKHI | J36: RAKS | L36: P/MEAL | N36: CWCJ | P36: =+O36 | Q36: MPRN | S36: =+R36
A37: WINDMIL | J37: RAKES/ WAGONS | K37: ODR | L37: WAGONS | M37: ODR | N37: MHPL | P37: =+O37 | Q37: SUNR | S37: =+R37
A38: PIPAVAV | I38: FREE | N38: GRFV | P38: =+O38 | Q38: SAUS | S38: =+R38
A39: KRIBHCO/MKIG | I39: RESTRICTION | N39: NCLW | P39: =+O39 | Q39: PPSP | S39: =+R39
A40: DAHEJ | I40: SPECIAL | N40: KPRK | P40: =+O40 | Q40: BHUN | S40: =+R40
...

Sheet LINK
A1: CURRENT YEAR COMMODITYWISE DAILY LOADING | AH1: CURRENT YEAR COMMODITYWISE MONTHLY LOADING | BO1: CURRENT YEAR COMMODITYWISE MONTHLY AVG LOADING | CW1: Yearly Progressive LDG up to last day of the prvious month | CX1: Cummulative no. of days up to last day of the previous month | CY1: CURRENT YEAR COMMODITYWISE YEARLY CUMMULATIVE LOADING | EF1: CURRENT YEAR COMMODITYWISE YEARLY AVG LOADING
A2: COMM | B2: 1 | C2: 2 | D2: 3 | E2: 4 | F2: 5 | G2: 6 | H2: 7 | I2: 8 | J2: 9 | K2: 10 | L2: 11 | M2: 12 | N2: 13 | O2: 14 | P2: 15 | Q2: 16 | R2: 17 | S2: 18 | T2: 19 | U2: 20 | V2: 21 | W2: 22 | X2: 23 | Y2: 24 | Z2: 25 | AA2: 26 | AB2: 27 | AC2: 28 | AD2: 29 | AE2: 30 | AF2: 31 | AH2: COMM | AI2: 1 | AJ2: 2 | AK2: 3 | AL2: 4 | AM2: 5 | AN2: 6 | AO2: 7 | AP2: 8 | AQ2: 9 | AR2: 10 | AS2: 11 | AT2: 12 | AU2: 13 | AV2: 14 | AW2: 15 | AX2: 16 | AY2: 17 | AZ2: 18 | BA2: 19 | BB2: 20 | BC2: 21 | BD2: 22 | BE2: 23 | BF2: 24 | BG2: 25 | BH2: 26 | BI2: 27 | BJ2: 28 | BK2: 29 | BL2: 30 | BM2: 31 | BO2: COMM | BP2: 1 | BQ2: 2 | BR2: 3 | BS2: 4 | BT2: 5 | BU2: 6 | BV2: 7 | BW2: 8 | BX2: 9 | BY2: 10 | BZ2: 11 | CA2: 12 | CB2: 13 | CC2: 14 | CD2: 15 | CE2: 16 | CF2: 17 | CG2: 18 | CH2: 19 | CI2: 20 | CJ2: 21 | CK2: 22 | CL2: 23 | CM2: 24 | CN2: 25 | CO2: 26 | CP2: 27 | CQ2: 28 | CR2: 29 | CS2: 30 | CT2: 31 | CV2: COMM | CX2: 306 | CY2: COMM | CZ2: 1 | DA2: 2 | DB2: 3 | DC2: 4 | DD2: 5 | DE2: 6 | DF2: 7 | DG2: 8 | DH2: 9 | DI2: 10 | DJ2: 11 | DK2: 12 | DL2: 13 | DM2: 14 | DN2: 15 | DO2: 16 | DP2: 17 | DQ2: 18 | DR2: 19 | DS2: 20 | DT2: 21 | DU2: 22 | DV2: 23 | DW2: 24 | DX2: 25 | DY2: 26 | DZ2: 27 | EA2: 28 | EB2: 29 | EC2: 30 | ED2: 31 | EF2: COMM | EG2: 307 | EH2: 308 | EI2: 309 | EJ2: 310 | EK2: 311 | EL2: 312 | EM2: 313 | EN2: 314 | EO2: 315 | EP2: 316 | EQ2: 317 | ER2: 318 | ES2: 319 | ET2: 320 | EU2: 321 | EV2: 322 | EW2: 323 | EX2: 324 | EY2: 325 | EZ2: 326 | FA2: 327 | FB2: 328 | FC2: 329 | FD2: 330 | FE2: 331 | FF2: 332 | FG2: 333 | FH2: 334 | FI2: 335 | FJ2: 336 | FK2: 337
A3: CEM | B3: ='1'!$D5 | C3: ='2'!$D5 | D3: ='3'!$D5 | E3: ='4'!$D5 | F3: ='5'!$D5 | G3: ='6'!$D5 | H3: ='7'!$D5 | I3: ='8'!$D5 | J3: ='9'!$D5 | K3: ='10'!$D5 | L3: ='11'!$D5 | M3: ='12'!$D5 | N3: ='13'!$D5 | O3: ='14'!$D5 | P3: ='15'!$D5 | Q3: ='16'!$D5 | R3: ='17'!$D5 | S3: ='18'!$D5 | T3: ='19'!$D5 | U3: ='20'!$D5 | V3: ='21'!$D5 | W3: ='22'!$D5 | X3: ='23'!$D5 | Y3: ='24'!$D5 | Z3: ='25'!$D5 | AA3: ='26'!$D5 | AB3: ='27'!$D5 | AC3: ='28'!$D5 | AD3: ='29'!$D5 | AH3: CEM | AI3: =B3 | AJ3: =AI3+C3 | AK3: =AJ3+D3 | AL3: =AK3+E3 | AM3: =AL3+F3 | AN3: =AM3+G3 | AO3: =AN3+H3 | AP3: =AO3+I3 | AQ3: =AP3+J3 | ... BK3: =BJ3+AD3 | BO3: CEM | BP3: =AI3/AI$2 | BQ3: =AJ3/AJ$2 | BR3: =AK3/AK$2 | BS3: =AL3/AL$2 | BT3: =AM3/AM$2 | BU3: =AN3/AN$2 | BV3: =AO3/AO$2 | BW3: =AP3/AP$2 | ... CR3: =BK3/BK$2 | CV3: CEM | CW3: 0 | CY3: CEM | CZ3: =CW3+B3 | DA3: =CZ3+C3 | DB3: =DA3+D3 | DC3: =DB3+E3 | DD3: =DC3+F3 | DE3: =DD3+G3 | DF3: =DE3+H3 | DG3: =DF3+I3 | DH3: =DG3+J3 | ... EB3: =EA3+AD3 | EF3: CEM | EG3: =CZ3/EG$2 | EH3: =DA3/EH$2 | EI3: =DB3/EI$2 | EJ3: =DC3/EJ$2 | EK3: =DD3/EK$2 | EL3: =DE3/EL$2 | EM3: =DF3/EM$2 | EN3: =DG3/EN$2 | ... FI3: =EB3/FI$2
A4: COAL | B4: ='1'!$D6 | C4: ='2'!$D6 | D4: ='3'!$D6 | E4: ='4'!$D6 | F4: ='5'!$D6 | G4: ='6'!$D6 | H4: ='7'!$D6 | I4: ='8'!$D6 | J4: ='9'!$D6 | K4: ='10'!$D6 | L4: ='11'!$D6 | M4: ='12'!$D6 | N4: ='13'!$D6 | O4: ='14'!$D6 | P4: ='15'!$D6 | Q4: ='16'!$D6 | R4: ='17'!$D6 | S4: ='18'!$D6 | T4: ='19'!$D6 | U4: ='20'!$D6 | V4: ='21'!$D6 | W4: ='22'!$D6 | X4: ='23'!$D6 | Y4: ='24'!$D6 | Z4: ='25'!$D6 | AA4: ='26'!$D6 | AB4: ='27'!$D6 | AC4: ='28'!$D6 | AD4: ='29'!$D6 | AH4: COAL | AI4: =B4 | AJ4: =AI4+C4 | AK4: =AJ4+D4 | AL4: =AK4+E4 | AM4: =AL4+F4 | AN4: =AM4+G4 | AO4: =AN4+H4 | AP4: =AO4+I4 | AQ4: =AP4+J4 | ... BK4: =BJ4+AD4 | BO4: COAL | BP4: =AI4/AI$2 | BQ4: =AJ4/AJ$2 | BR4: =AK4/AK$2 | BS4: =AL4/AL$2 | BT4: =AM4/AM$2 | BU4: =AN4/AN$2 | BV4: =AO4/AO$2 | BW4: =AP4/AP$2 | ... CR4: =BK4/BK$2 | CV4: COAL | CW4: 0 | CY4: COAL | CZ4: =CW4+B4 | DA4: =CZ4+C4 | DB4: =DA4+D4 | DC4: =DB4+E4 | DD4: =DC4+F4 | DE4: =DD4+G4 | DF4: =DE4+H4 | DG4: =DF4+I4 | DH4: =DG4+J4 | ... EB4: =EA4+AD4 | EF4: COAL | EG4: =CZ4/EG$2 | EH4: =DA4/EH$2 | EI4: =DB4/EI$2 | EJ4: =DC4/EJ$2 | EK4: =DD4/EK$2 | EL4: =DE4/EL$2 | EM4: =DF4/EM$2 | EN4: =DG4/EN$2 | ... FI4: =EB4/FI$2
A5: CONT | B5: ='1'!$D7 | C5: ='2'!$D7 | D5: ='3'!$D7 | E5: ='4'!$D7 | F5: ='5'!$D7 | G5: ='6'!$D7 | H5: ='7'!$D7 | I5: ='8'!$D7 | J5: ='9'!$D7 | K5: ='10'!$D7 | L5: ='11'!$D7 | M5: ='12'!$D7 | N5: ='13'!$D7 | O5: ='14'!$D7 | P5: ='15'!$D7 | Q5: ='16'!$D7 | R5: ='17'!$D7 | S5: ='18'!$D7 | T5: ='19'!$D7 | U5: ='20'!$D7 | V5: ='21'!$D7 | W5: ='22'!$D7 | X5: ='23'!$D7 | Y5: ='24'!$D7 | Z5: ='25'!$D7 | AA5: ='26'!$D7 | AB5: ='27'!$D7 | AC5: ='28'!$D7 | AD5: ='29'!$D7 | AH5: CONT | AI5: =B5 | AJ5: =AI5+C5 | AK5: =AJ5+D5 | AL5: =AK5+E5 | AM5: =AL5+F5 | AN5: =AM5+G5 | AO5: =AN5+H5 | AP5: =AO5+I5 | AQ5: =AP5+J5 | ... BK5: =BJ5+AD5 | BO5: CONT | BP5: =AI5/AI$2 | BQ5: =AJ5/AJ$2 | BR5: =AK5/AK$2 | BS5: =AL5/AL$2 | BT5: =AM5/AM$2 | BU5: =AN5/AN$2 | BV5: =AO5/AO$2 | BW5: =AP5/AP$2 | ... CR5: =BK5/BK$2 | CV5: CONT | CW5: 0 | CY5: CONT | CZ5: =CW5+B5 | DA5: =CZ5+C5 | DB5: =DA5+D5 | DC5: =DB5+E5 | DD5: =DC5+F5 | DE5: =DD5+G5 | DF5: =DE5+H5 | DG5: =DF5+I5 | DH5: =DG5+J5 | ... EB5: =EA5+AD5 | EF5: CONT | EG5: =CZ5/EG$2 | EH5: =DA5/EH$2 | EI5: =DB5/EI$2 | EJ5: =DC5/EJ$2 | EK5: =DD5/EK$2 | EL5: =DE5/EL$2 | EM5: =DF5/EM$2 | EN5: =DG5/EN$2 | ... FI5: =EB5/FI$2
A6: FERT | B6: ='1'!$D8 | C6: ='2'!$D8 | D6: ='3'!$D8 | E6: ='4'!$D8 | F6: ='5'!$D8 | G6: ='6'!$D8 | H6: ='7'!$D8 | I6: ='8'!$D8 | J6: ='9'!$D8 | K6: ='10'!$D8 | L6: ='11'!$D8 | M6: ='12'!$D8 | N6: ='13'!$D8 | O6: ='14'!$D8 | P6: ='15'!$D8 | Q6: ='16'!$D8 | R6: ='17'!$D8 | S6: ='18'!$D8 | T6: ='19'!$D8 | U6: ='20'!$D8 | V6: ='21'!$D8 | W6: ='22'!$D8 | X6: ='23'!$D8 | Y6: ='24'!$D8 | Z6: ='25'!$D8 | AA6: ='26'!$D8 | AB6: ='27'!$D8 | AC6: ='28'!$D8 | AD6: ='29'!$D8 | AH6: FERT | AI6: =B6 | AJ6: =AI6+C6 | AK6: =AJ6+D6 | AL6: =AK6+E6 | AM6: =AL6+F6 | AN6: =AM6+G6 | AO6: =AN6+H6 | AP6: =AO6+I6 | AQ6: =AP6+J6 | ... BK6: =BJ6+AD6 | BO6: FERT | BP6: =AI6/AI$2 | BQ6: =AJ6/AJ$2 | BR6: =AK6/AK$2 | BS6: =AL6/AL$2 | BT6: =AM6/AM$2 | BU6: =AN6/AN$2 | BV6: =AO6/AO$2 | BW6: =AP6/AP$2 | ... CR6: =BK6/BK$2 | CV6: FERT | CW6: 0 | CY6: FERT | CZ6: =CW6+B6 | DA6: =CZ6+C6 | DB6: =DA6+D6 | DC6: =DB6+E6 | DD6: =DC6+F6 | DE6: =DD6+G6 | DF6: =DE6+H6 | DG6: =DF6+I6 | DH6: =DG6+J6 | ... EB6: =EA6+AD6 | EF6: FERT | EG6: =CZ6/EG$2 | EH6: =DA6/EH$2 | EI6: =DB6/EI$2 | EJ6: =DC6/EJ$2 | EK6: =DD6/EK$2 | EL6: =DE6/EL$2 | EM6: =DF6/EM$2 | EN6: =DG6/EN$2 | ... FI6: =EB6/FI$2
A7: IMFT | B7: ='1'!$D9 | C7: ='2'!$D9 | D7: ='3'!$D9 | E7: ='4'!$D9 | F7: ='5'!$D9 | G7: ='6'!$D9 | H7: ='7'!$D9 | I7: ='8'!$D9 | J7: ='9'!$D9 | K7: ='10'!$D9 | L7: ='11'!$D9 | M7: ='12'!$D9 | N7: ='13'!$D9 | O7: ='14'!$D9 | P7: ='15'!$D9 | Q7: ='16'!$D9 | R7: ='17'!$D9 | S7: ='18'!$D9 | T7: ='19'!$D9 | U7: ='20'!$D9 | V7: ='21'!$D9 | W7: ='22'!$D9 | X7: ='23'!$D9 | Y7: ='24'!$D9 | Z7: ='25'!$D9 | AA7: ='26'!$D9 | AB7: ='27'!$D9 | AC7: ='28'!$D9 | AD7: ='29'!$D9 | AH7: IMFT | AI7: =B7 | AJ7: =AI7+C7 | AK7: =AJ7+D7 | AL7: =AK7+E7 | AM7: =AL7+F7 | AN7: =AM7+G7 | AO7: =AN7+H7 | AP7: =AO7+I7 | AQ7: =AP7+J7 | ... BK7: =BJ7+AD7 | BO7: IMFT | BP7: =AI7/AI$2 | BQ7: =AJ7/AJ$2 | BR7: =AK7/AK$2 | BS7: =AL7/AL$2 | BT7: =AM7/AM$2 | BU7: =AN7/AN$2 | BV7: =AO7/AO$2 | BW7: =AP7/AP$2 | ... CR7: =BK7/BK$2 | CV7: IMFT | CW7: 0 | CY7: IMFT | CZ7: =CW7+B7 | DA7: =CZ7+C7 | DB7: =DA7+D7 | DC7: =DB7+E7 | DD7: =DC7+F7 | DE7: =DD7+G7 | DF7: =DE7+H7 | DG7: =DF7+I7 | DH7: =DG7+J7 | ... EB7: =EA7+AD7 | EF7: IMFT | EG7: =CZ7/EG$2 | EH7: =DA7/EH$2 | EI7: =DB7/EI$2 | EJ7: =DC7/EJ$2 | EK7: =DD7/EK$2 | EL7: =DE7/EL$2 | EM7: =DF7/EM$2 | EN7: =DG7/EN$2 | ... FI7: =EB7/FI$2
A8: POL | B8: ='1'!$D10 | C8: ='2'!$D10 | D8: ='3'!$D10 | E8: ='4'!$D10 | F8: ='5'!$D10 | G8: ='6'!$D10 | H8: ='7'!$D10 | I8: ='8'!$D10 | J8: ='9'!$D10 | K8: ='10'!$D10 | L8: ='11'!$D10 | M8: ='12'!$D10 | N8: ='13'!$D10 | O8: ='14'!$D10 | P8: ='15'!$D10 | Q8: ='16'!$D10 | R8: ='17'!$D10 | S8: ='18'!$D10 | T8: ='19'!$D10 | U8: ='20'!$D10 | V8: ='21'!$D10 | W8: ='22'!$D10 | X8: ='23'!$D10 | Y8: ='24'!$D10 | Z8: ='25'!$D10 | AA8: ='26'!$D10 | AB8: ='27'!$D10 | AC8: ='28'!$D10 | AD8: ='29'!$D10 | AH8: POL | AI8: =B8 | AJ8: =AI8+C8 | AK8: =AJ8+D8 | AL8: =AK8+E8 | AM8: =AL8+F8 | AN8: =AM8+G8 | AO8: =AN8+H8 | AP8: =AO8+I8 | AQ8: =AP8+J8 | ... BK8: =BJ8+AD8 | BO8: POL | BP8: =AI8/AI$2 | BQ8: =AJ8/AJ$2 | BR8: =AK8/AK$2 | BS8: =AL8/AL$2 | BT8: =AM8/AM$2 | BU8: =AN8/AN$2 | BV8: =AO8/AO$2 | BW8: =AP8/AP$2 | ... CR8: =BK8/BK$2 | CV8: POL | CW8: 0 | CY8: POL | CZ8: =CW8+B8 | DA8: =CZ8+C8 | DB8: =DA8+D8 | DC8: =DB8+E8 | DD8: =DC8+F8 | DE8: =DD8+G8 | DF8: =DE8+H8 | DG8: =DF8+I8 | DH8: =DG8+J8 | ... EB8: =EA8+AD8 | EF8: POL | EG8: =CZ8/EG$2 | EH8: =DA8/EH$2 | EI8: =DB8/EI$2 | EJ8: =DC8/EJ$2 | EK8: =DD8/EK$2 | EL8: =DE8/EL$2 | EM8: =DF8/EM$2 | EN8: =DG8/EN$2 | ... FI8: =EB8/FI$2
A9: SALT | B9: ='1'!$D11 | C9: ='2'!$D11 | D9: ='3'!$D11 | E9: ='4'!$D11 | F9: ='5'!$D11 | G9: ='6'!$D11 | H9: ='7'!$D11 | I9: ='8'!$D11 | J9: ='9'!$D11 | K9: ='10'!$D11 | L9: ='11'!$D11 | M9: ='12'!$D11 | N9: ='13'!$D11 | O9: ='14'!$D11 | P9: ='15'!$D11 | Q9: ='16'!$D11 | R9: ='17'!$D11 | S9: ='18'!$D11 | T9: ='19'!$D11 | U9: ='20'!$D11 | V9: ='21'!$D11 | W9: ='22'!$D11 | X9: ='23'!$D11 | Y9: ='24'!$D11 | Z9: ='25'!$D11 | AA9: ='26'!$D11 | AB9: ='27'!$D11 | AC9: ='28'!$D11 | AD9: ='29'!$D11 | AH9: SALT | AI9: =B9 | AJ9: =AI9+C9 | AK9: =AJ9+D9 | AL9: =AK9+E9 | AM9: =AL9+F9 | AN9: =AM9+G9 | AO9: =AN9+H9 | AP9: =AO9+I9 | AQ9: =AP9+J9 | ... BK9: =BJ9+AD9 | BO9: SALT | BP9: =AI9/AI$2 | BQ9: =AJ9/AJ$2 | BR9: =AK9/AK$2 | BS9: =AL9/AL$2 | BT9: =AM9/AM$2 | BU9: =AN9/AN$2 | BV9: =AO9/AO$2 | BW9: =AP9/AP$2 | ... CR9: =BK9/BK$2 | CV9: SALT | CW9: 0 | CY9: SALT | CZ9: =CW9+B9 | DA9: =CZ9+C9 | DB9: =DA9+D9 | DC9: =DB9+E9 | DD9: =DC9+F9 | DE9: =DD9+G9 | DF9: =DE9+H9 | DG9: =DF9+I9 | DH9: =DG9+J9 | ... EB9: =EA9+AD9 | EF9: SALT | EG9: =CZ9/EG$2 | EH9: =DA9/EH$2 | EI9: =DB9/EI$2 | EJ9: =DC9/EJ$2 | EK9: =DD9/EK$2 | EL9: =DE9/EL$2 | EM9: =DF9/EM$2 | EN9: =DG9/EN$2 | ... FI9: =EB9/FI$2
A10: STEEL | B10: ='1'!$D12 | C10: ='2'!$D12 | D10: ='3'!$D12 | E10: ='4'!$D12 | F10: ='5'!$D12 | G10: ='6'!$D12 | H10: ='7'!$D12 | I10: ='8'!$D12 | J10: ='9'!$D12 | K10: ='10'!$D12 | L10: ='11'!$D12 | M10: ='12'!$D12 | N10: ='13'!$D12 | O10: ='14'!$D12 | P10: ='15'!$D12 | Q10: ='16'!$D12 | R10: ='17'!$D12 | S10: ='18'!$D12 | T10: ='19'!$D12 | U10: ='20'!$D12 | V10: ='21'!$D12 | W10: ='22'!$D12 | X10: ='23'!$D12 | Y10: ='24'!$D12 | Z10: ='25'!$D12 | AA10: ='26'!$D12 | AB10: ='27'!$D12 | AC10: ='28'!$D12 | AD10: ='29'!$D12 | AH10: STEEL | AI10: =B10 | AJ10: =AI10+C10 | AK10: =AJ10+D10 | AL10: =AK10+E10 | AM10: =AL10+F10 | AN10: =AM10+G10 | AO10: =AN10+H10 | AP10: =AO10+I10 | AQ10: =AP10+J10 | ... BK10: =BJ10+AD10 | BO10: STEEL | BP10: =AI10/AI$2 | BQ10: =AJ10/AJ$2 | BR10: =AK10/AK$2 | BS10: =AL10/AL$2 | BT10: =AM10/AM$2 | BU10: =AN10/AN$2 | BV10: =AO10/AO$2 | BW10: =AP10/AP$2 | ... CR10: =BK10/BK$2 | CV10: STEEL | CW10: 0 | CY10: STEEL | CZ10: =CW10+B10 | DA10: =CZ10+C10 | DB10: =DA10+D10 | DC10: =DB10+E10 | DD10: =DC10+F10 | DE10: =DD10+G10 | DF10: =DE10+H10 | DG10: =DF10+I10 | DH10: =DG10+J10 | ... EB10: =EA10+AD10 | EF10: STEEL | EG10: =CZ10/EG$2 | EH10: =DA10/EH$2 | EI10: =DB10/EI$2 | EJ10: =DC10/EJ$2 | EK10: =DD10/EK$2 | EL10: =DE10/EL$2 | EM10: =DF10/EM$2 | EN10: =DG10/EN$2 | ... FI10: =EB10/FI$2
A11: DOC | B11: ='1'!$D13 | C11: ='2'!$D13 | D11: ='3'!$D13 | E11: ='4'!$D13 | F11: ='5'!$D13 | G11: ='6'!$D13 | H11: ='7'!$D13 | I11: ='8'!$D13 | J11: ='9'!$D13 | K11: ='10'!$D13 | L11: ='11'!$D13 | M11: ='12'!$D13 | N11: ='13'!$D13 | O11: ='14'!$D13 | P11: ='15'!$D13 | Q11: ='16'!$D13 | R11: ='17'!$D13 | S11: ='18'!$D13 | T11: ='19'!$D13 | U11: ='20'!$D13 | V11: ='21'!$D13 | W11: ='22'!$D13 | X11: ='23'!$D13 | Y11: ='24'!$D13 | Z11: ='25'!$D13 | AA11: ='26'!$D13 | AB11: ='27'!$D13 | AC11: ='28'!$D13 | AD11: ='29'!$D13 | AH11: DOC | AI11: =B11 | AJ11: =AI11+C11 | AK11: =AJ11+D11 | AL11: =AK11+E11 | AM11: =AL11+F11 | AN11: =AM11+G11 | AO11: =AN11+H11 | AP11: =AO11+I11 | AQ11: =AP11+J11 | ... BK11: =BJ11+AD11 | BO11: DOC | BP11: =AI11/AI$2 | BQ11: =AJ11/AJ$2 | BR11: =AK11/AK$2 | BS11: =AL11/AL$2 | BT11: =AM11/AM$2 | BU11: =AN11/AN$2 | BV11: =AO11/AO$2 | BW11: =AP11/AP$2 | ... CR11: =BK11/BK$2 | CV11: DOC | CW11: 0 | CY11: DOC | CZ11: =CW11+B11 | DA11: =CZ11+C11 | DB11: =DA11+D11 | DC11: =DB11+E11 | DD11: =DC11+F11 | DE11: =DD11+G11 | DF11: =DE11+H11 | DG11: =DF11+I11 | DH11: =DG11+J11 | ... EB11: =EA11+AD11 | EF11: DOC | EG11: =CZ11/EG$2 | EH11: =DA11/EH$2 | EI11: =DB11/EI$2 | EJ11: =DC11/EJ$2 | EK11: =DD11/EK$2 | EL11: =DE11/EL$2 | EM11: =DF11/EM$2 | EN11: =DG11/EN$2 | ... FI11: =EB11/FI$2
A12: FG | B12: ='1'!$D14 | C12: ='2'!$D14 | D12: ='3'!$D14 | E12: ='4'!$D14 | F12: ='5'!$D14 | G12: ='6'!$D14 | H12: ='7'!$D14 | I12: ='8'!$D14 | J12: ='9'!$D14 | K12: ='10'!$D14 | L12: ='11'!$D14 | M12: ='12'!$D14 | N12: ='13'!$D14 | O12: ='14'!$D14 | P12: ='15'!$D14 | Q12: ='16'!$D14 | R12: ='17'!$D14 | S12: ='18'!$D14 | T12: ='19'!$D14 | U12: ='20'!$D14 | V12: ='21'!$D14 | W12: ='22'!$D14 | X12: ='23'!$D14 | Y12: ='24'!$D14 | Z12: ='25'!$D14 | AA12: ='26'!$D14 | AB12: ='27'!$D14 | AC12: ='28'!$D14 | AD12: ='29'!$D14 | AH12: FG | AI12: =B12 | AJ12: =AI12+C12 | AK12: =AJ12+D12 | AL12: =AK12+E12 | AM12: =AL12+F12 | AN12: =AM12+G12 | AO12: =AN12+H12 | AP12: =AO12+I12 | AQ12: =AP12+J12 | ... BK12: =BJ12+AD12 | BO12: FG | BP12: =AI12/AI$2 | BQ12: =AJ12/AJ$2 | BR12: =AK12/AK$2 | BS12: =AL12/AL$2 | BT12: =AM12/AM$2 | BU12: =AN12/AN$2 | BV12: =AO12/AO$2 | BW12: =AP12/AP$2 | ... CR12: =BK12/BK$2 | CV12: FG | CW12: 0 | CY12: FG | CZ12: =CW12+B12 | DA12: =CZ12+C12 | DB12: =DA12+D12 | DC12: =DB12+E12 | DD12: =DC12+F12 | DE12: =DD12+G12 | DF12: =DE12+H12 | DG12: =DF12+I12 | DH12: =DG12+J12 | ... EB12: =EA12+AD12 | EF12: FG | EG12: =CZ12/EG$2 | EH12: =DA12/EH$2 | EI12: =DB12/EI$2 | EJ12: =DC12/EJ$2 | EK12: =DD12/EK$2 | EL12: =DE12/EL$2 | EM12: =DF12/EM$2 | EN12: =DG12/EN$2 | ... FI12: =EB12/FI$2
A13: CHEM | B13: ='1'!$D15 | C13: ='2'!$D15 | D13: ='3'!$D15 | E13: ='4'!$D15 | F13: ='5'!$D15 | G13: ='6'!$D15 | H13: ='7'!$D15 | I13: ='8'!$D15 | J13: ='9'!$D15 | K13: ='10'!$D15 | L13: ='11'!$D15 | M13: ='12'!$D15 | N13: ='13'!$D15 | O13: ='14'!$D15 | P13: ='15'!$D15 | Q13: ='16'!$D15 | R13: ='17'!$D15 | S13: ='18'!$D15 | T13: ='19'!$D15 | U13: ='20'!$D15 | V13: ='21'!$D15 | W13: ='22'!$D15 | X13: ='23'!$D15 | Y13: ='24'!$D15 | Z13: ='25'!$D15 | AA13: ='26'!$D15 | AB13: ='27'!$D15 | AC13: ='28'!$D15 | AD13: ='29'!$D15 | AH13: CHEM | AI13: =B13 | AJ13: =AI13+C13 | AK13: =AJ13+D13 | AL13: =AK13+E13 | AM13: =AL13+F13 | AN13: =AM13+G13 | AO13: =AN13+H13 | AP13: =AO13+I13 | AQ13: =AP13+J13 | ... BK13: =BJ13+AD13 | BO13: CHEM | BP13: =AI13/AI$2 | BQ13: =AJ13/AJ$2 | BR13: =AK13/AK$2 | BS13: =AL13/AL$2 | BT13: =AM13/AM$2 | BU13: =AN13/AN$2 | BV13: =AO13/AO$2 | BW13: =AP13/AP$2 | ... CR13: =BK13/BK$2 | CV13: CHEM | CW13: 0 | CY13: CHEM | CZ13: =CW13+B13 | DA13: =CZ13+C13 | DB13: =DA13+D13 | DC13: =DB13+E13 | DD13: =DC13+F13 | DE13: =DD13+G13 | DF13: =DE13+H13 | DG13: =DF13+I13 | DH13: =DG13+J13 | ... EB13: =EA13+AD13 | EF13: CHEM | EG13: =CZ13/EG$2 | EH13: =DA13/EH$2 | EI13: =DB13/EI$2 | EJ13: =DC13/EJ$2 | EK13: =DD13/EK$2 | EL13: =DE13/EL$2 | EM13: =DF13/EM$2 | EN13: =DG13/EN$2 | ... FI13: =EB13/FI$2
A14: AUTO | B14: ='1'!$D16 | C14: ='2'!$D16 | D14: ='3'!$D16 | E14: ='4'!$D16 | F14: ='5'!$D16 | G14: ='6'!$D16 | H14: ='7'!$D16 | I14: ='8'!$D16 | J14: ='9'!$D16 | K14: ='10'!$D16 | L14: ='11'!$D16 | M14: ='12'!$D16 | N14: ='13'!$D16 | O14: ='14'!$D16 | P14: ='15'!$D16 | Q14: ='16'!$D16 | R14: ='17'!$D16 | S14: ='18'!$D16 | T14: ='19'!$D16 | U14: ='20'!$D16 | V14: ='21'!$D16 | W14: ='22'!$D16 | X14: ='23'!$D16 | Y14: ='24'!$D16 | Z14: ='25'!$D16 | AA14: ='26'!$D16 | AB14: ='27'!$D16 | AC14: ='28'!$D16 | AD14: ='29'!$D16 | AH14: AUTO | AI14: =B14 | AJ14: =AI14+C14 | AK14: =AJ14+D14 | AL14: =AK14+E14 | AM14: =AL14+F14 | AN14: =AM14+G14 | AO14: =AN14+H14 | AP14: =AO14+I14 | AQ14: =AP14+J14 | ... BK14: =BJ14+AD14 | BO14: AUTO | BP14: =AI14/AI$2 | BQ14: =AJ14/AJ$2 | BR14: =AK14/AK$2 | BS14: =AL14/AL$2 | BT14: =AM14/AM$2 | BU14: =AN14/AN$2 | BV14: =AO14/AO$2 | BW14: =AP14/AP$2 | ... CR14: =BK14/BK$2 | CV14: AUTO | CW14: 0 | CY14: AUTO | CZ14: =CW14+B14 | DA14: =CZ14+C14 | DB14: =DA14+D14 | DC14: =DB14+E14 | DD14: =DC14+F14 | DE14: =DD14+G14 | DF14: =DE14+H14 | DG14: =DF14+I14 | DH14: =DG14+J14 | ... EB14: =EA14+AD14 | EF14: AUTO | EG14: =CZ14/EG$2 | EH14: =DA14/EH$2 | EI14: =DB14/EI$2 | EJ14: =DC14/EJ$2 | EK14: =DD14/EK$2 | EL14: =DE14/EL$2 | EM14: =DF14/EM$2 | EN14: =DG14/EN$2 | ... FI14: =EB14/FI$2
A15: OTHERS | B15: ='1'!$D17 | C15: ='2'!$D17 | D15: ='3'!$D17 | E15: ='4'!$D17 | F15: ='5'!$D17 | G15: ='6'!$D17 | H15: ='7'!$D17 | I15: ='8'!$D17 | J15: ='9'!$D17 | K15: ='10'!$D17 | L15: ='11'!$D17 | M15: ='12'!$D17 | N15: ='13'!$D17 | O15: ='14'!$D17 | P15: ='15'!$D17 | Q15: ='16'!$D17 | R15: ='17'!$D17 | S15: ='18'!$D17 | T15: ='19'!$D17 | U15: ='20'!$D17 | V15: ='21'!$D17 | W15: ='22'!$D17 | X15: ='23'!$D17 | Y15: ='24'!$D17 | Z15: ='25'!$D17 | AA15: ='26'!$D17 | AB15: ='27'!$D17 | AC15: ='28'!$D17 | AD15: ='29'!$D17 | AH15: OTHERS | AI15: =B15 | AJ15: =AI15+C15 | AK15: =AJ15+D15 | AL15: =AK15+E15 | AM15: =AL15+F15 | AN15: =AM15+G15 | AO15: =AN15+H15 | AP15: =AO15+I15 | AQ15: =AP15+J15 | ... BK15: =BJ15+AD15 | BO15: OTHERS | BP15: =AI15/AI$2 | BQ15: =AJ15/AJ$2 | BR15: =AK15/AK$2 | BS15: =AL15/AL$2 | BT15: =AM15/AM$2 | BU15: =AN15/AN$2 | BV15: =AO15/AO$2 | BW15: =AP15/AP$2 | ... CR15: =BK15/BK$2 | CV15: OTHERS | CW15: 0 | CY15: OTHERS | CZ15: =CW15+B15 | DA15: =CZ15+C15 | DB15: =DA15+D15 | DC15: =DB15+E15 | DD15: =DC15+F15 | DE15: =DD15+G15 | DF15: =DE15+H15 | DG15: =DF15+I15 | DH15: =DG15+J15 | ... EB15: =EA15+AD15 | EF15: OTHERS | EG15: =CZ15/EG$2 | EH15: =DA15/EH$2 | EI15: =DB15/EI$2 | EJ15: =DC15/EJ$2 | EK15: =DD15/EK$2 | EL15: =DE15/EL$2 | EM15: =DF15/EM$2 | EN15: =DG15/EN$2 | ... FI15: =EB15/FI$2
A16: TOTAL | B16: =SUM(B3:B15) | C16: =SUM(C3:C15) | D16: =SUM(D3:D15) | E16: =SUM(E3:E15) | F16: =SUM(F3:F15) | G16: =SUM(G3:G15) | H16: =SUM(H3:H15) | I16: =SUM(I3:I15) | ... AD16: =SUM(AD3:AD15) | AH16: TOTAL | AI16: =SUM(AI3:AI15) | AJ16: =SUM(AJ3:AJ15) | AK16: =SUM(AK3:AK15) | AL16: =SUM(AL3:AL15) | AM16: =SUM(AM3:AM15) | AN16: =SUM(AN3:AN15) | AO16: =SUM(AO3:AO15) | AP16: =SUM(AP3:AP15) | ... BM16: =SUM(BM3:BM15) | BO16: TOTAL | BP16: =SUM(BP3:BP15) | BQ16: =SUM(BQ3:BQ15) | BR16: =SUM(BR3:BR15) | BS16: =SUM(BS3:BS15) | BT16: =SUM(BT3:BT15) | BU16: =SUM(BU3:BU15) | BV16: =SUM(BV3:BV15) | BW16: =SUM(BW3:BW15) | ... CT16: =SUM(CT3:CT15) | CV16: TOTAL | CW16: =SUM(CW3:CW15) | CY16: TOTAL | CZ16: =SUM(CZ3:CZ15) | DA16: =SUM(DA3:DA15) | DB16: =SUM(DB3:DB15) | DC16: =SUM(DC3:DC15) | DD16: =SUM(DD3:DD15) | DE16: =SUM(DE3:DE15) | DF16: =SUM(DF3:DF15) | DG16: =SUM(DG3:DG15) | ... ED16: =SUM(ED3:ED15) | EF16: TOTAL | EG16: =SUM(EG3:EG15) | EH16: =SUM(EH3:EH15) | EI16: =SUM(EI3:EI15) | EJ16: =SUM(EJ3:EJ15) | EK16: =SUM(EK3:EK15) | EL16: =SUM(EL3:EL15) | EM16: =SUM(EM3:EM15) | EN16: =SUM(EN3:EN15) | ... FK16: =SUM(FK3:FK15)
A18: CURRENT YEAR DIVISIONWISE DAILY LOADING | AH18: CURRENT YEAR DIVISIONWISE MONTHLY LOADING | BO18: CURRENT YEAR DIVISIONWISE MONTHLY AVG LOADING | CY18: CURRENT YEAR DIVISIONWISE YEARLY CUMMULATIVE LOADING | EF18: CURRENT YEAR DIVISIONWISE YEARLY AVG LOADING
A19: DIV | B19: 1 | C19: 2 | D19: 3 | E19: 4 | F19: 5 | G19: 6 | H19: 7 | I19: 8 | J19: 9 | K19: 10 | L19: 11 | M19: 12 | N19: 13 | O19: 14 | P19: 15 | Q19: 16 | R19: 17 | S19: 18 | T19: 19 | U19: 20 | V19: 21 | W19: 22 | X19: 23 | Y19: 24 | Z19: 25 | AA19: 26 | AB19: 27 | AC19: 28 | AD19: 29 | AE19: 30 | AF19: 31 | AH19: DIV | AI19: 1 | AJ19: 2 | AK19: 3 | AL19: 4 | AM19: 5 | AN19: 6 | AO19: 7 | AP19: 8 | AQ19: 9 | AR19: 10 | AS19: 11 | AT19: 12 | AU19: 13 | AV19: 14 | AW19: 15 | AX19: 16 | AY19: 17 | AZ19: 18 | BA19: 19 | BB19: 20 | BC19: 21 | BD19: 22 | BE19: 23 | BF19: 24 | BG19: 25 | BH19: 26 | BI19: 27 | BJ19: 28 | BK19: 29 | BL19: 30 | BM19: 31 | BO19: DIV | BP19: 1 | BQ19: 2 | BR19: 3 | BS19: 4 | BT19: 5 | BU19: 6 | BV19: 7 | BW19: 8 | BX19: 9 | BY19: 10 | BZ19: 11 | CA19: 12 | CB19: 13 | CC19: 14 | CD19: 15 | CE19: 16 | CF19: 17 | CG19: 18 | CH19: 19 | CI19: 20 | CJ19: 21 | CK19: 22 | CL19: 23 | CM19: 24 | CN19: 25 | CO19: 26 | CP19: 27 | CQ19: 28 | CR19: 29 | CS19: 30 | CT19: 31 | CV19: DIV | CY19: DIV | CZ19: 1 | DA19: 2 | DB19: 3 | DC19: 4 | DD19: 5 | DE19: 6 | DF19: 7 | DG19: 8 | DH19: 9 | DI19: 10 | DJ19: 11 | DK19: 12 | DL19: 13 | DM19: 14 | DN19: 15 | DO19: 16 | DP19: 17 | DQ19: 18 | DR19: 19 | DS19: 20 | DT19: 21 | DU19: 22 | DV19: 23 | DW19: 24 | DX19: 25 | DY19: 26 | DZ19: 27 | EA19: 28 | EB19: 29 | EC19: 30 | ED19: 31 | EF19: DIV | EG19: =EG2 | EH19: =EH2 | EI19: =EI2 | EJ19: =EJ2 | EK19: =EK2 | EL19: =EL2 | EM19: =EM2 | EN19: =EN2 | ... FK19: =FK2
A20: ADI | B20: ='1'!$D21 | C20: ='2'!$D21 | D20: ='3'!$D21 | E20: ='4'!$D21 | F20: ='5'!$D21 | G20: ='6'!$D21 | H20: ='7'!$D21 | I20: ='8'!$D21 | J20: ='9'!$D21 | K20: ='10'!$D21 | L20: ='11'!$D21 | M20: ='12'!$D21 | N20: ='13'!$D21 | O20: ='14'!$D21 | P20: ='15'!$D21 | Q20: ='16'!$D21 | R20: ='17'!$D21 | S20: ='18'!$D21 | T20: ='19'!$D21 | U20: ='20'!$D21 | V20: ='21'!$D21 | W20: ='22'!$D21 | X20: ='23'!$D21 | Y20: ='24'!$D21 | Z20: ='25'!$D21 | AA20: ='26'!$D21 | AB20: ='27'!$D21 | AC20: ='28'!$D21 | AD20: ='29'!$D21 | AH20: ADI | AI20: =B20 | AJ20: =AI20+C20 | AK20: =AJ20+D20 | AL20: =AK20+E20 | AM20: =AL20+F20 | AN20: =AM20+G20 | AO20: =AN20+H20 | AP20: =AO20+I20 | AQ20: =AP20+J20 | ... BK20: =BJ20+AD20 | BO20: ADI | BP20: =AI20/AI$2 | BQ20: =AJ20/AJ$2 | BR20: =AK20/AK$2 | BS20: =AL20/AL$2 | BT20: =AM20/AM$2 | BU20: =AN20/AN$2 | BV20: =AO20/AO$2 | BW20: =AP20/AP$2 | ... CR20: =BK20/BK$2 | CV20: ADI | CW20: 0 | CY20: ADI | CZ20: =CW20+B20 | DA20: =CZ20+C20 | DB20: =DA20+D20 | DC20: =DB20+E20 | DD20: =DC20+F20 | DE20: =DD20+G20 | DF20: =DE20+H20 | DG20: =DF20+I20 | DH20: =DG20+J20 | ... EB20: =EA20+AD20 | EF20: ADI | EG20: =CZ20/EG$2 | EH20: =DA20/EH$2 | EI20: =DB20/EI$2 | EJ20: =DC20/EJ$2 | EK20: =DD20/EK$2 | EL20: =DE20/EL$2 | EM20: =DF20/EM$2 | EN20: =DG20/EN$2 | ... FI20: =EB20/FI$2
A21: GIMB | B21: ='1'!$D22 | C21: ='2'!$D22 | D21: ='3'!$D22 | E21: ='4'!$D22 | F21: ='5'!$D22 | G21: ='6'!$D22 | H21: ='7'!$D22 | I21: ='8'!$D22 | J21: ='9'!$D22 | K21: ='10'!$D22 | L21: ='11'!$D22 | M21: ='12'!$D22 | N21: ='13'!$D22 | O21: ='14'!$D22 | P21: ='15'!$D22 | Q21: ='16'!$D22 | R21: ='17'!$D22 | S21: ='18'!$D22 | T21: ='19'!$D22 | U21: ='20'!$D22 | V21: ='21'!$D22 | W21: ='22'!$D22 | X21: ='23'!$D22 | Y21: ='24'!$D22 | Z21: ='25'!$D22 | AA21: ='26'!$D22 | AB21: ='27'!$D22 | AC21: ='28'!$D22 | AD21: ='29'!$D22 | AH21: GIMB | AI21: =B21 | AJ21: =AI21+C21 | AK21: =AJ21+D21 | AL21: =AK21+E21 | AM21: =AL21+F21 | AN21: =AM21+G21 | AO21: =AN21+H21 | AP21: =AO21+I21 | AQ21: =AP21+J21 | ... BK21: =BJ21+AD21 | BO21: GIMB | BP21: =AI21/AI$2 | BQ21: =AJ21/AJ$2 | BR21: =AK21/AK$2 | BS21: =AL21/AL$2 | BT21: =AM21/AM$2 | BU21: =AN21/AN$2 | BV21: =AO21/AO$2 | BW21: =AP21/AP$2 | ... CR21: =BK21/BK$2 | CV21: GIMB | CW21: 0 | CY21: GIMB | CZ21: =CW21+B21 | DA21: =CZ21+C21 | DB21: =DA21+D21 | DC21: =DB21+E21 | DD21: =DC21+F21 | DE21: =DD21+G21 | DF21: =DE21+H21 | DG21: =DF21+I21 | DH21: =DG21+J21 | ... EB21: =EA21+AD21 | EF21: GIMB | EG21: =CZ21/EG$2 | EH21: =DA21/EH$2 | EI21: =DB21/EI$2 | EJ21: =DC21/EJ$2 | EK21: =DD21/EK$2 | EL21: =DE21/EL$2 | EM21: =DF21/EM$2 | EN21: =DG21/EN$2 | ... FI21: =EB21/FI$2
A22: BCT | B22: ='1'!$D23 | C22: ='2'!$D23 | D22: ='3'!$D23 | E22: ='4'!$D23 | F22: ='5'!$D23 | G22: ='6'!$D23 | H22: ='7'!$D23 | I22: ='8'!$D23 | J22: ='9'!$D23 | K22: ='10'!$D23 | L22: ='11'!$D23 | M22: ='12'!$D23 | N22: ='13'!$D23 | O22: ='14'!$D23 | P22: ='15'!$D23 | Q22: ='16'!$D23 | R22: ='17'!$D23 | S22: ='18'!$D23 | T22: ='19'!$D23 | U22: ='20'!$D23 | V22: ='21'!$D23 | W22: ='22'!$D23 | X22: ='23'!$D23 | Y22: ='24'!$D23 | Z22: ='25'!$D23 | AA22: ='26'!$D23 | AB22: ='27'!$D23 | AC22: ='28'!$D23 | AD22: ='29'!$D23 | AH22: BCT | AI22: =B22 | AJ22: =AI22+C22 | AK22: =AJ22+D22 | AL22: =AK22+E22 | AM22: =AL22+F22 | AN22: =AM22+G22 | AO22: =AN22+H22 | AP22: =AO22+I22 | AQ22: =AP22+J22 | ... BK22: =BJ22+AD22 | BO22: BCT | BP22: =AI22/AI$2 | BQ22: =AJ22/AJ$2 | BR22: =AK22/AK$2 | BS22: =AL22/AL$2 | BT22: =AM22/AM$2 | BU22: =AN22/AN$2 | BV22: =AO22/AO$2 | BW22: =AP22/AP$2 | ... CR22: =BK22/BK$2 | CV22: BCT | CW22: 0 | CY22: BCT | CZ22: =CW22+B22 | DA22: =CZ22+C22 | DB22: =DA22+D22 | DC22: =DB22+E22 | DD22: =DC22+F22 | DE22: =DD22+G22 | DF22: =DE22+H22 | DG22: =DF22+I22 | DH22: =DG22+J22 | ... EB22: =EA22+AD22 | EF22: BCT | EG22: =CZ22/EG$2 | EH22: =DA22/EH$2 | EI22: =DB22/EI$2 | EJ22: =DC22/EJ$2 | EK22: =DD22/EK$2 | EL22: =DE22/EL$2 | EM22: =DF22/EM$2 | EN22: =DG22/EN$2 | ... FI22: =EB22/FI$2
A23: BRC | B23: ='1'!$D24 | C23: ='2'!$D24 | D23: ='3'!$D24 | E23: ='4'!$D24 | F23: ='5'!$D24 | G23: ='6'!$D24 | H23: ='7'!$D24 | I23: ='8'!$D24 | J23: ='9'!$D24 | K23: ='10'!$D24 | L23: ='11'!$D24 | M23: ='12'!$D24 | N23: ='13'!$D24 | O23: ='14'!$D24 | P23: ='15'!$D24 | Q23: ='16'!$D24 | R23: ='17'!$D24 | S23: ='18'!$D24 | T23: ='19'!$D24 | U23: ='20'!$D24 | V23: ='21'!$D24 | W23: ='22'!$D24 | X23: ='23'!$D24 | Y23: ='24'!$D24 | Z23: ='25'!$D24 | AA23: ='26'!$D24 | AB23: ='27'!$D24 | AC23: ='28'!$D24 | AD23: ='29'!$D24 | AH23: BRC | AI23: =B23 | AJ23: =AI23+C23 | AK23: =AJ23+D23 | AL23: =AK23+E23 | AM23: =AL23+F23 | AN23: =AM23+G23 | AO23: =AN23+H23 | AP23: =AO23+I23 | AQ23: =AP23+J23 | ... BK23: =BJ23+AD23 | BO23: BRC | BP23: =AI23/AI$2 | BQ23: =AJ23/AJ$2 | BR23: =AK23/AK$2 | BS23: =AL23/AL$2 | BT23: =AM23/AM$2 | BU23: =AN23/AN$2 | BV23: =AO23/AO$2 | BW23: =AP23/AP$2 | ... CR23: =BK23/BK$2 | CV23: BRC | CW23: 0 | CY23: BRC | CZ23: =CW23+B23 | DA23: =CZ23+C23 | DB23: =DA23+D23 | DC23: =DB23+E23 | DD23: =DC23+F23 | DE23: =DD23+G23 | DF23: =DE23+H23 | DG23: =DF23+I23 | DH23: =DG23+J23 | ... EB23: =EA23+AD23 | EF23: BRC | EG23: =CZ23/EG$2 | EH23: =DA23/EH$2 | EI23: =DB23/EI$2 | EJ23: =DC23/EJ$2 | EK23: =DD23/EK$2 | EL23: =DE23/EL$2 | EM23: =DF23/EM$2 | EN23: =DG23/EN$2 | ... FI23: =EB23/FI$2
A24: RJT | B24: ='1'!$D25 | C24: ='2'!$D25 | D24: ='3'!$D25 | E24: ='4'!$D25 | F24: ='5'!$D25 | G24: ='6'!$D25 | H24: ='7'!$D25 | I24: ='8'!$D25 | J24: ='9'!$D25 | K24: ='10'!$D25 | L24: ='11'!$D25 | M24: ='12'!$D25 | N24: ='13'!$D25 | O24: ='14'!$D25 | P24: ='15'!$D25 | Q24: ='16'!$D25 | R24: ='17'!$D25 | S24: ='18'!$D25 | T24: ='19'!$D25 | U24: ='20'!$D25 | V24: ='21'!$D25 | W24: ='22'!$D25 | X24: ='23'!$D25 | Y24: ='24'!$D25 | Z24: ='25'!$D25 | AA24: ='26'!$D25 | AB24: ='27'!$D25 | AC24: ='28'!$D25 | AD24: ='29'!$D25 | AH24: RJT | AI24: =B24 | AJ24: =AI24+C24 | AK24: =AJ24+D24 | AL24: =AK24+E24 | AM24: =AL24+F24 | AN24: =AM24+G24 | AO24: =AN24+H24 | AP24: =AO24+I24 | AQ24: =AP24+J24 | ... BK24: =BJ24+AD24 | BO24: RJT | BP24: =AI24/AI$2 | BQ24: =AJ24/AJ$2 | BR24: =AK24/AK$2 | BS24: =AL24/AL$2 | BT24: =AM24/AM$2 | BU24: =AN24/AN$2 | BV24: =AO24/AO$2 | BW24: =AP24/AP$2 | ... CR24: =BK24/BK$2 | CV24: RJT | CW24: 0 | CY24: RJT | CZ24: =CW24+B24 | DA24: =CZ24+C24 | DB24: =DA24+D24 | DC24: =DB24+E24 | DD24: =DC24+F24 | DE24: =DD24+G24 | DF24: =DE24+H24 | DG24: =DF24+I24 | DH24: =DG24+J24 | ... EB24: =EA24+AD24 | EF24: RJT | EG24: =CZ24/EG$2 | EH24: =DA24/EH$2 | EI24: =DB24/EI$2 | EJ24: =DC24/EJ$2 | EK24: =DD24/EK$2 | EL24: =DE24/EL$2 | EM24: =DF24/EM$2 | EN24: =DG24/EN$2 | ... FI24: =EB24/FI$2
A25: BVP | B25: ='1'!$D26 | C25: ='2'!$D26 | D25: ='3'!$D26 | E25: ='4'!$D26 | F25: ='5'!$D26 | G25: ='6'!$D26 | H25: ='7'!$D26 | I25: ='8'!$D26 | J25: ='9'!$D26 | K25: ='10'!$D26 | L25: ='11'!$D26 | M25: ='12'!$D26 | N25: ='13'!$D26 | O25: ='14'!$D26 | P25: ='15'!$D26 | Q25: ='16'!$D26 | R25: ='17'!$D26 | S25: ='18'!$D26 | T25: ='19'!$D26 | U25: ='20'!$D26 | V25: ='21'!$D26 | W25: ='22'!$D26 | X25: ='23'!$D26 | Y25: ='24'!$D26 | Z25: ='25'!$D26 | AA25: ='26'!$D26 | AB25: ='27'!$D26 | AC25: ='28'!$D26 | AD25: ='29'!$D26 | AH25: BVP | AI25: =B25 | AJ25: =AI25+C25 | AK25: =AJ25+D25 | AL25: =AK25+E25 | AM25: =AL25+F25 | AN25: =AM25+G25 | AO25: =AN25+H25 | AP25: =AO25+I25 | AQ25: =AP25+J25 | ... BK25: =BJ25+AD25 | BO25: BVP | BP25: =AI25/AI$2 | BQ25: =AJ25/AJ$2 | BR25: =AK25/AK$2 | BS25: =AL25/AL$2 | BT25: =AM25/AM$2 | BU25: =AN25/AN$2 | BV25: =AO25/AO$2 | BW25: =AP25/AP$2 | ... CR25: =BK25/BK$2 | CV25: BVP | CW25: 0 | CY25: BVP | CZ25: =CW25+B25 | DA25: =CZ25+C25 | DB25: =DA25+D25 | DC25: =DB25+E25 | DD25: =DC25+F25 | DE25: =DD25+G25 | DF25: =DE25+H25 | DG25: =DF25+I25 | DH25: =DG25+J25 | ... EB25: =EA25+AD25 | EF25: BVP | EG25: =CZ25/EG$2 | EH25: =DA25/EH$2 | EI25: =DB25/EI$2 | EJ25: =DC25/EJ$2 | EK25: =DD25/EK$2 | EL25: =DE25/EL$2 | EM25: =DF25/EM$2 | EN25: =DG25/EN$2 | ... FI25: =EB25/FI$2
A26: RTM | B26: ='1'!$D27 | C26: ='2'!$D27 | D26: ='3'!$D27 | E26: ='4'!$D27 | F26: ='5'!$D27 | G26: ='6'!$D27 | H26: ='7'!$D27 | I26: ='8'!$D27 | J26: ='9'!$D27 | K26: ='10'!$D27 | L26: ='11'!$D27 | M26: ='12'!$D27 | N26: ='13'!$D27 | O26: ='14'!$D27 | P26: ='15'!$D27 | Q26: ='16'!$D27 | R26: ='17'!$D27 | S26: ='18'!$D27 | T26: ='19'!$D27 | U26: ='20'!$D27 | V26: ='21'!$D27 | W26: ='22'!$D27 | X26: ='23'!$D27 | Y26: ='24'!$D27 | Z26: ='25'!$D27 | AA26: ='26'!$D27 | AB26: ='27'!$D27 | AC26: ='28'!$D27 | AD26: ='29'!$D27 | AH26: RTM | AI26: =B26 | AJ26: =AI26+C26 | AK26: =AJ26+D26 | AL26: =AK26+E26 | AM26: =AL26+F26 | AN26: =AM26+G26 | AO26: =AN26+H26 | AP26: =AO26+I26 | AQ26: =AP26+J26 | ... BK26: =BJ26+AD26 | BO26: RTM | BP26: =AI26/AI$2 | BQ26: =AJ26/AJ$2 | BR26: =AK26/AK$2 | BS26: =AL26/AL$2 | BT26: =AM26/AM$2 | BU26: =AN26/AN$2 | BV26: =AO26/AO$2 | BW26: =AP26/AP$2 | ... CR26: =BK26/BK$2 | CV26: RTM | CW26: 0 | CY26: RTM | CZ26: =CW26+B26 | DA26: =CZ26+C26 | DB26: =DA26+D26 | DC26: =DB26+E26 | DD26: =DC26+F26 | DE26: =DD26+G26 | DF26: =DE26+H26 | DG26: =DF26+I26 | DH26: =DG26+J26 | ... EB26: =EA26+AD26 | EF26: RTM | EG26: =CZ26/EG$2 | EH26: =DA26/EH$2 | EI26: =DB26/EI$2 | EJ26: =DC26/EJ$2 | EK26: =DD26/EK$2 | EL26: =DE26/EL$2 | EM26: =DF26/EM$2 | EN26: =DG26/EN$2 | ... FI26: =EB26/FI$2
A27: TOTAL | B27: =SUM(B20:B26) | C27: =SUM(C20:C26) | D27: =SUM(D20:D26) | E27: =SUM(E20:E26) | F27: =SUM(F20:F26) | G27: =SUM(G20:G26) | H27: =SUM(H20:H26) | I27: =SUM(I20:I26) | ... AD27: =SUM(AD20:AD26) | AH27: TOTAL | AI27: =SUM(AI20:AI26) | AJ27: =SUM(AJ20:AJ26) | AK27: =SUM(AK20:AK26) | AL27: =SUM(AL20:AL26) | AM27: =SUM(AM20:AM26) | AN27: =SUM(AN20:AN26) | AO27: =SUM(AO20:AO26) | AP27: =SUM(AP20:AP26) | ... BM27: =SUM(BM20:BM26) | BO27: TOTAL | BP27: =SUM(BP20:BP26) | BQ27: =SUM(BQ20:BQ26) | BR27: =SUM(BR20:BR26) | BS27: =SUM(BS20:BS26) | BT27: =SUM(BT20:BT26) | BU27: =SUM(BU20:BU26) | BV27: =SUM(BV20:BV26) | BW27: =SUM(BW20:BW26) | ... CT27: =SUM(CT20:CT26) | CV27: TOTAL | CW27: =SUM(CW20:CW26) | CY27: TOTAL | CZ27: =SUM(CZ20:CZ26) | DA27: =SUM(DA20:DA26) | DB27: =SUM(DB20:DB26) | DC27: =SUM(DC20:DC26) | DD27: =SUM(DD20:DD26) | DE27: =SUM(DE20:DE26) | DF27: =SUM(DF20:DF26) | DG27: =SUM(DG20:DG26) | ... ED27: =SUM(ED20:ED26) | EF27: TOTAL | EG27: =SUM(EG20:EG26) | EH27: =SUM(EH20:EH26) | EI27: =SUM(EI20:EI26) | EJ27: =SUM(EJ20:EJ26) | EK27: =SUM(EK20:EK26) | EL27: =SUM(EL20:EL26) | EM27: =SUM(EM20:EM26) | EN27: =SUM(EN20:EN26) | ... FI27: =SUM(FI20:FI26) | FJ27: =EC27/FJ$19 | FK27: =ED27/FK$19
A30: LAST YEAR COMMODITYWISE DAILY LOADING ( COPY PASTE VALUE ONLY) | AH30: LAST YEAR COMMODITY WISEMONTHLY CUMMULATIVE LOADING ( COPY PASTE VALUE ONLY) | BO30: LAST YEAR COMMODITYWISE MONTHLY AVGLOADING ( COPY PASTE VALUE ONLY) | CY30: LAST YEAR COMMODITYWISE YEARLY AVGLOADING ( COPY PASTE VALUE ONLY)
A31: COMM | B31: 1 | C31: 2 | D31: 3 | E31: 4 | F31: 5 | G31: 6 | H31: 7 | I31: 8 | J31: 9 | K31: 10 | L31: 11 | M31: 12 | N31: 13 | O31: 14 | P31: 15 | Q31: 16 | R31: 17 | S31: 18 | T31: 19 | U31: 20 | V31: 21 | W31: 22 | X31: 23 | Y31: 24 | Z31: 25 | AA31: 26 | AB31: 27 | AC31: 28 | AD31: 29 | AE31: 30 | AF31: 31 | AH31: COMM | AI31: 1 | AJ31: 2 | AK31: 3 | AL31: 4 | AM31: 5 | AN31: 6 | AO31: 7 | AP31: 8 | AQ31: 9 | AR31: 10 | AS31: 11 | AT31: 12 | AU31: 13 | AV31: 14 | AW31: 15 | AX31: 16 | AY31: 17 | AZ31: 18 | BA31: 19 | BB31: 20 | BC31: 21 | BD31: 22 | BE31: 23 | BF31: 24 | BG31: 25 | BH31: 26 | BI31: 27 | BJ31: 28 | BK31: 29 | BL31: 30 | BM31: 31 | BO31: COMM | BP31: 1 | BQ31: 2 | BR31: 3 | BS31: 4 | BT31: 5 | BU31: 6 | BV31: 7 | BW31: 8 | BX31: 9 | BY31: 10 | BZ31: 11 | CA31: 12 | CB31: 13 | CC31: 14 | CD31: 15 | CE31: 16 | CF31: 17 | CG31: 18 | CH31: 19 | CI31: 20 | CJ31: 21 | CK31: 22 | CL31: 23 | CM31: 24 | CN31: 25 | CO31: 26 | CP31: 27 | CQ31: 28 | CR31: 29 | CS31: 30 | CT31: 31 | CY31: COMM | CZ31: 1 | DA31: 2 | DB31: 3 | DC31: 4 | DD31: 5 | DE31: 6 | DF31: 7 | DG31: 8 | DH31: 9 | DI31: 10 | DJ31: 11 | DK31: 12 | DL31: 13 | DM31: 14 | DN31: 15 | DO31: 16 | DP31: 17 | DQ31: 18 | DR31: 19 | DS31: 20 | DT31: 21 | DU31: 22 | DV31: 23 | DW31: 24 | DX31: 25 | DY31: 26 | DZ31: 27 | EA31: 28 | EB31: 29 | EC31: 30 | ED31: 31
A32: CEM | B32: 0 | C32: 0 | D32: 0 | E32: 0 | F32: 0 | G32: 0 | H32: 0 | I32: 0 | J32: 0 | K32: 0 | L32: 0 | M32: 0 | N32: 0 | O32: 0 | P32: 0 | Q32: 0 | R32: 0 | S32: 0 | T32: 0 | U32: 0 | V32: 0 | W32: 0 | X32: 0 | Y32: 0 | Z32: 0 | AA32: 0 | AB32: 0 | AC32: 0 | AD32: 0 | AH32: CEM | AI32: =SUM($B32:B32)/1 | AJ32: =SUM($B32:C32)/2 | AK32: =SUM($B32:D32)/3 | AL32: =SUM($B32:E32)/4 | AM32: =SUM($B32:F32)/5 | AN32: =SUM($B32:G32)/6 | AO32: =SUM($B32:H32)/7 | AP32: =SUM($B32:I32)/8 | AQ32: =SUM($B32:J32)/9 | AR32: =SUM($B32:K32)/10 | AS32: =SUM($B32:L32)/11 | AT32: =SUM($B32:M32)/12 | AU32: =SUM($B32:N32)/13 | AV32: =SUM($B32:O32)/14 | AW32: =SUM($B32:P32)/15 | AX32: =SUM($B32:Q32)/16 | AY32: =SUM($B32:R32)/17 | AZ32: =SUM($B32:S32)/18 | BA32: =SUM($B32:T32)/19 | BB32: =SUM($B32:U32)/20 | BC32: =SUM($B32:V32)/21 | BD32: =SUM($B32:W32)/22 | BE32: =SUM($B32:X32)/23 | BF32: =SUM($B32:Y32)/24 | BG32: =SUM($B32:Z32)/25 | BH32: =SUM($B32:AA32)/26 | BI32: =SUM($B32:AB32)/27 | BJ32: =SUM($B32:AC32)/28 | BK32: =SUM($B32:AD32)/29 | BO32: CEM | BP32: =(0.0+SUM($B32:B32))/(306+1) | BQ32: =(0.0+SUM($B32:C32))/(306+2) | BR32: =(0.0+SUM($B32:D32))/(306+3) | BS32: =(0.0+SUM($B32:E32))/(306+4) | BT32: =(0.0+SUM($B32:F32))/(306+5) | BU32: =(0.0+SUM($B32:G32))/(306+6) | BV32: =(0.0+SUM($B32:H32))/(306+7) | BW32: =(0.0+SUM($B32:I32))/(306+8) | BX32: =(0.0+SUM($B32:J32))/(306+9) | BY32: =(0.0+SUM($B32:K32))/(306+10) | BZ32: =(0.0+SUM($B32:L32))/(306+11) | CA32: =(0.0+SUM($B32:M32))/(306+12) | CB32: =(0.0+SUM($B32:N32))/(306+13) | CC32: =(0.0+SUM($B32:O32))/(306+14) | CD32: =(0.0+SUM($B32:P32))/(306+15) | CE32: =(0.0+SUM($B32:Q32))/(306+16) | CF32: =(0.0+SUM($B32:R32))/(306+17) | CG32: =(0.0+SUM($B32:S32))/(306+18) | CH32: =(0.0+SUM($B32:T32))/(306+19) | CI32: =(0.0+SUM($B32:U32))/(306+20) | CJ32: =(0.0+SUM($B32:V32))/(306+21) | CK32: =(0.0+SUM($B32:W32))/(306+22) | CL32: =(0.0+SUM($B32:X32))/(306+23) | CM32: =(0.0+SUM($B32:Y32))/(306+24) | CN32: =(0.0+SUM($B32:Z32))/(306+25) | CO32: =(0.0+SUM($B32:AA32))/(306+26) | CP32: =(0.0+SUM($B32:AB32))/(306+27) | CQ32: =(0.0+SUM($B32:AC32))/(306+28) | CR32: =(0.0+SUM($B32:AD32))/(306+29) | CY32: CEM | CZ32: 586.47154 | DA32: 586.20968 | DB32: 586.896 | DC32: 586.03175 | DD32: 585.10236 | DE32: 585.79688 | DF32: 584.89147 | DG32: 583.61538 | DH32: 581.9771 | DI32: 581.12121 | DJ32: 579.13534 | DK32: 577.28358 | DL32: 576.0963 | DM32: 574.75 | DN32: 573.43796 | DO32: 571.69565 | DP32: 570.31655 | DQ32: 568.35714 | DR32: 566.52482 | DS32: 565.5 | DT32: 564.92308 | DU32: 565.26389 | DV32: 564.37931 | DW32: 562.46575 | DX32: 562.30612 | DY32: 561.39865 | DZ32: 561.62416 | EA32: 561.84 | EB32: 560.61589 | EC32: 559.39474 | ED32: 560.01307
A33: COAL | B33: 0 | C33: 0 | D33: 0 | E33: 0 | F33: 0 | G33: 0 | H33: 0 | I33: 0 | J33: 0 | K33: 0 | L33: 0 | M33: 0 | N33: 0 | O33: 0 | P33: 0 | Q33: 0 | R33: 0 | S33: 0 | T33: 0 | U33: 0 | V33: 0 | W33: 0 | X33: 0 | Y33: 0 | Z33: 0 | AA33: 0 | AB33: 0 | AC33: 0 | AD33: 0 | AH33: COAL | AI33: =SUM($B33:B33)/1 | AJ33: =SUM($B33:C33)/2 | AK33: =SUM($B33:D33)/3 | AL33: =SUM($B33:E33)/4 | AM33: =SUM($B33:F33)/5 | AN33: =SUM($B33:G33)/6 | AO33: =SUM($B33:H33)/7 | AP33: =SUM($B33:I33)/8 | AQ33: =SUM($B33:J33)/9 | AR33: =SUM($B33:K33)/10 | AS33: =SUM($B33:L33)/11 | AT33: =SUM($B33:M33)/12 | AU33: =SUM($B33:N33)/13 | AV33: =SUM($B33:O33)/14 | AW33: =SUM($B33:P33)/15 | AX33: =SUM($B33:Q33)/16 | AY33: =SUM($B33:R33)/17 | AZ33: =SUM($B33:S33)/18 | BA33: =SUM($B33:T33)/19 | BB33: =SUM($B33:U33)/20 | BC33: =SUM($B33:V33)/21 | BD33: =SUM($B33:W33)/22 | BE33: =SUM($B33:X33)/23 | BF33: =SUM($B33:Y33)/24 | BG33: =SUM($B33:Z33)/25 | BH33: =SUM($B33:AA33)/26 | BI33: =SUM($B33:AB33)/27 | BJ33: =SUM($B33:AC33)/28 | BK33: =SUM($B33:AD33)/29 | BO33: COAL | BP33: =(0.0+SUM($B33:B33))/(306+1) | BQ33: =(0.0+SUM($B33:C33))/(306+2) | BR33: =(0.0+SUM($B33:D33))/(306+3) | BS33: =(0.0+SUM($B33:E33))/(306+4) | BT33: =(0.0+SUM($B33:F33))/(306+5) | BU33: =(0.0+SUM($B33:G33))/(306+6) | BV33: =(0.0+SUM($B33:H33))/(306+7) | BW33: =(0.0+SUM($B33:I33))/(306+8) | BX33: =(0.0+SUM($B33:J33))/(306+9) | BY33: =(0.0+SUM($B33:K33))/(306+10) | BZ33: =(0.0+SUM($B33:L33))/(306+11) | CA33: =(0.0+SUM($B33:M33))/(306+12) | CB33: =(0.0+SUM($B33:N33))/(306+13) | CC33: =(0.0+SUM($B33:O33))/(306+14) | CD33: =(0.0+SUM($B33:P33))/(306+15) | CE33: =(0.0+SUM($B33:Q33))/(306+16) | CF33: =(0.0+SUM($B33:R33))/(306+17) | CG33: =(0.0+SUM($B33:S33))/(306+18) | CH33: =(0.0+SUM($B33:T33))/(306+19) | CI33: =(0.0+SUM($B33:U33))/(306+20) | CJ33: =(0.0+SUM($B33:V33))/(306+21) | CK33: =(0.0+SUM($B33:W33))/(306+22) | CL33: =(0.0+SUM($B33:X33))/(306+23) | CM33: =(0.0+SUM($B33:Y33))/(306+24) | CN33: =(0.0+SUM($B33:Z33))/(306+25) | CO33: =(0.0+SUM($B33:AA33))/(306+26) | CP33: =(0.0+SUM($B33:AB33))/(306+27) | CQ33: =(0.0+SUM($B33:AC33))/(306+28) | CR33: =(0.0+SUM($B33:AD33))/(306+29) | CY33: COAL | CZ33: 205.2439 | DA33: 206.8871 | DB33: 207.112 | DC33: 207.3254 | DD33: 207.04724 | DE33: 206.35156 | DF33: 204.75194 | DG33: 203.59231 | DH33: 202.93893 | DI33: 202.69697 | DJ33: 202.93233 | DK33: 204.02239 | DL33: 204.23704 | DM33: 204.875 | DN33: 205.94161 | DO33: 206.13043 | DP33: 206.7482 | DQ33: 206.95 | DR33: 206.71631 | DS33: 206.07042 | DT33: 206.25874 | DU33: 205.63889 | DV33: 206.24138 | DW33: 206.82192 | DX33: 207.41497 | DY33: 207.98649 | DZ33: 207.7651 | EA33: 208.33333 | EB33: 208.09272 | EC33: 207.49342 | ED33: 207.29412
A34: CONT | B34: 0 | C34: 0 | D34: 0 | E34: 0 | F34: 0 | G34: 0 | H34: 0 | I34: 0 | J34: 0 | K34: 0 | L34: 0 | M34: 0 | N34: 0 | O34: 0 | P34: 0 | Q34: 0 | R34: 0 | S34: 0 | T34: 0 | U34: 0 | V34: 0 | W34: 0 | X34: 0 | Y34: 0 | Z34: 0 | AA34: 0 | AB34: 0 | AC34: 0 | AD34: 0 | AH34: CONT | AI34: =SUM($B34:B34)/1 | AJ34: =SUM($B34:C34)/2 | AK34: =SUM($B34:D34)/3 | AL34: =SUM($B34:E34)/4 | AM34: =SUM($B34:F34)/5 | AN34: =SUM($B34:G34)/6 | AO34: =SUM($B34:H34)/7 | AP34: =SUM($B34:I34)/8 | AQ34: =SUM($B34:J34)/9 | AR34: =SUM($B34:K34)/10 | AS34: =SUM($B34:L34)/11 | AT34: =SUM($B34:M34)/12 | AU34: =SUM($B34:N34)/13 | AV34: =SUM($B34:O34)/14 | AW34: =SUM($B34:P34)/15 | AX34: =SUM($B34:Q34)/16 | AY34: =SUM($B34:R34)/17 | AZ34: =SUM($B34:S34)/18 | BA34: =SUM($B34:T34)/19 | BB34: =SUM($B34:U34)/20 | BC34: =SUM($B34:V34)/21 | BD34: =SUM($B34:W34)/22 | BE34: =SUM($B34:X34)/23 | BF34: =SUM($B34:Y34)/24 | BG34: =SUM($B34:Z34)/25 | BH34: =SUM($B34:AA34)/26 | BI34: =SUM($B34:AB34)/27 | BJ34: =SUM($B34:AC34)/28 | BK34: =SUM($B34:AD34)/29 | BO34: CONT | BP34: =(0.0+SUM($B34:B34))/(306+1) | BQ34: =(0.0+SUM($B34:C34))/(306+2) | BR34: =(0.0+SUM($B34:D34))/(306+3) | BS34: =(0.0+SUM($B34:E34))/(306+4) | BT34: =(0.0+SUM($B34:F34))/(306+5) | BU34: =(0.0+SUM($B34:G34))/(306+6) | BV34: =(0.0+SUM($B34:H34))/(306+7) | BW34: =(0.0+SUM($B34:I34))/(306+8) | BX34: =(0.0+SUM($B34:J34))/(306+9) | BY34: =(0.0+SUM($B34:K34))/(306+10) | BZ34: =(0.0+SUM($B34:L34))/(306+11) | CA34: =(0.0+SUM($B34:M34))/(306+12) | CB34: =(0.0+SUM($B34:N34))/(306+13) | CC34: =(0.0+SUM($B34:O34))/(306+14) | CD34: =(0.0+SUM($B34:P34))/(306+15) | CE34: =(0.0+SUM($B34:Q34))/(306+16) | CF34: =(0.0+SUM($B34:R34))/(306+17) | CG34: =(0.0+SUM($B34:S34))/(306+18) | CH34: =(0.0+SUM($B34:T34))/(306+19) | CI34: =(0.0+SUM($B34:U34))/(306+20) | CJ34: =(0.0+SUM($B34:V34))/(306+21) | CK34: =(0.0+SUM($B34:W34))/(306+22) | CL34: =(0.0+SUM($B34:X34))/(306+23) | CM34: =(0.0+SUM($B34:Y34))/(306+24) | CN34: =(0.0+SUM($B34:Z34))/(306+25) | CO34: =(0.0+SUM($B34:AA34))/(306+26) | CP34: =(0.0+SUM($B34:AB34))/(306+27) | CQ34: =(0.0+SUM($B34:AC34))/(306+28) | CR34: =(0.0+SUM($B34:AD34))/(306+29) | CY34: CONT | CZ34: 2560.4146 | DA34: 2559.75 | DB34: 2559.616 | DC34: 2560.5159 | DD34: 2562.4173 | DE34: 2563.6562 | DF34: 2565.5271 | DG34: 2562.2308 | DH34: 2563.0992 | DI34: 2560.7727 | DJ34: 2562.2632 | DK34: 2557.9328 | DL34: 2556.5926 | DM34: 2555.1324 | DN34: 2555.4818 | DO34: 2556.8913 | DP34: 2555.1942 | DQ34: 2554.2857 | DR34: 2553.3262 | DS34: 2551.162 | DT34: 2550.3427 | DU34: 2550.8472 | DV34: 2551.6345 | DW34: 2552.9658 | DX34: 2556.102 | DY34: 2557.4797 | DZ34: 2557.3893 | EA34: 2556.5333 | EB34: 2554.5166 | EC34: 2555.0921 | ED34: 2555.8693
A35: FERT | B35: 0 | C35: 0 | D35: 0 | E35: 0 | F35: 0 | G35: 0 | H35: 0 | I35: 0 | J35: 0 | K35: 0 | L35: 0 | M35: 0 | N35: 0 | O35: 0 | P35: 0 | Q35: 0 | R35: 0 | S35: 0 | T35: 0 | U35: 0 | V35: 0 | W35: 0 | X35: 0 | Y35: 0 | Z35: 0 | AA35: 0 | AB35: 0 | AC35: 0 | AD35: 0 | AH35: FERT | AI35: =SUM($B35:B35)/1 | AJ35: =SUM($B35:C35)/2 | AK35: =SUM($B35:D35)/3 | AL35: =SUM($B35:E35)/4 | AM35: =SUM($B35:F35)/5 | AN35: =SUM($B35:G35)/6 | AO35: =SUM($B35:H35)/7 | AP35: =SUM($B35:I35)/8 | AQ35: =SUM($B35:J35)/9 | AR35: =SUM($B35:K35)/10 | AS35: =SUM($B35:L35)/11 | AT35: =SUM($B35:M35)/12 | AU35: =SUM($B35:N35)/13 | AV35: =SUM($B35:O35)/14 | AW35: =SUM($B35:P35)/15 | AX35: =SUM($B35:Q35)/16 | AY35: =SUM($B35:R35)/17 | AZ35: =SUM($B35:S35)/18 | BA35: =SUM($B35:T35)/19 | BB35: =SUM($B35:U35)/20 | BC35: =SUM($B35:V35)/21 | BD35: =SUM($B35:W35)/22 | BE35: =SUM($B35:X35)/23 | BF35: =SUM($B35:Y35)/24 | BG35: =SUM($B35:Z35)/25 | BH35: =SUM($B35:AA35)/26 | BI35: =SUM($B35:AB35)/27 | BJ35: =SUM($B35:AC35)/28 | BK35: =SUM($B35:AD35)/29 | BO35: FERT | BP35: =(0.0+SUM($B35:B35))/(306+1) | BQ35: =(0.0+SUM($B35:C35))/(306+2) | BR35: =(0.0+SUM($B35:D35))/(306+3) | BS35: =(0.0+SUM($B35:E35))/(306+4) | BT35: =(0.0+SUM($B35:F35))/(306+5) | BU35: =(0.0+SUM($B35:G35))/(306+6) | BV35: =(0.0+SUM($B35:H35))/(306+7) | BW35: =(0.0+SUM($B35:I35))/(306+8) | BX35: =(0.0+SUM($B35:J35))/(306+9) | BY35: =(0.0+SUM($B35:K35))/(306+10) | BZ35: =(0.0+SUM($B35:L35))/(306+11) | CA35: =(0.0+SUM($B35:M35))/(306+12) | CB35: =(0.0+SUM($B35:N35))/(306+13) | CC35: =(0.0+SUM($B35:O35))/(306+14) | CD35: =(0.0+SUM($B35:P35))/(306+15) | CE35: =(0.0+SUM($B35:Q35))/(306+16) | CF35: =(0.0+SUM($B35:R35))/(306+17) | CG35: =(0.0+SUM($B35:S35))/(306+18) | CH35: =(0.0+SUM($B35:T35))/(306+19) | CI35: =(0.0+SUM($B35:U35))/(306+20) | CJ35: =(0.0+SUM($B35:V35))/(306+21) | CK35: =(0.0+SUM($B35:W35))/(306+22) | CL35: =(0.0+SUM($B35:X35))/(306+23) | CM35: =(0.0+SUM($B35:Y35))/(306+24) | CN35: =(0.0+SUM($B35:Z35))/(306+25) | CO35: =(0.0+SUM($B35:AA35))/(306+26) | CP35: =(0.0+SUM($B35:AB35))/(306+27) | CQ35: =(0.0+SUM($B35:AC35))/(306+28) | CR35: =(0.0+SUM($B35:AD35))/(306+29) | CY35: FERT | CZ35: 310.7561 | DA35: 311.08065 | DB35: 311.168 | DC35: 311.83333 | DD35: 311.9685 | DE35: 312.07812 | DF35: 312.58915 | DG35: 312.44615 | DH35: 312.9542 | DI35: 312.9697 | DJ35: 313.28571 | DK35: 313.41791 | DL35: 313.58519 | DM35: 314.02206 | DN35: 315.07299 | DO35: 315.34058 | DP35: 316.04317 | DQ35: 317.12857 | DR35: 319.2695 | DS35: 319.50704 | DT35: 320.27972 | DU35: 320.9375 | DV35: 321.32414 | DW35: 321.28767 | DX35: 321.7483 | DY35: 321.20946 | DZ35: 321.83221 | EA35: 323.08667 | EB35: 323.41722 | EC35: 324.09211 | ED35: 323.72549
A36: IMFT | B36: 0 | C36: 0 | D36: 0 | E36: 0 | F36: 0 | G36: 0 | H36: 0 | I36: 0 | J36: 0 | K36: 0 | L36: 0 | M36: 0 | N36: 0 | O36: 0 | P36: 0 | Q36: 0 | R36: 0 | S36: 0 | T36: 0 | U36: 0 | V36: 0 | W36: 0 | X36: 0 | Y36: 0 | Z36: 0 | AA36: 0 | AB36: 0 | AC36: 0 | AD36: 0 | AH36: IMFT | AI36: =SUM($B36:B36)/1 | AJ36: =SUM($B36:C36)/2 | AK36: =SUM($B36:D36)/3 | AL36: =SUM($B36:E36)/4 | AM36: =SUM($B36:F36)/5 | AN36: =SUM($B36:G36)/6 | AO36: =SUM($B36:H36)/7 | AP36: =SUM($B36:I36)/8 | AQ36: =SUM($B36:J36)/9 | AR36: =SUM($B36:K36)/10 | AS36: =SUM($B36:L36)/11 | AT36: =SUM($B36:M36)/12 | AU36: =SUM($B36:N36)/13 | AV36: =SUM($B36:O36)/14 | AW36: =SUM($B36:P36)/15 | AX36: =SUM($B36:Q36)/16 | AY36: =SUM($B36:R36)/17 | AZ36: =SUM($B36:S36)/18 | BA36: =SUM($B36:T36)/19 | BB36: =SUM($B36:U36)/20 | BC36: =SUM($B36:V36)/21 | BD36: =SUM($B36:W36)/22 | BE36: =SUM($B36:X36)/23 | BF36: =SUM($B36:Y36)/24 | BG36: =SUM($B36:Z36)/25 | BH36: =SUM($B36:AA36)/26 | BI36: =SUM($B36:AB36)/27 | BJ36: =SUM($B36:AC36)/28 | BK36: =SUM($B36:AD36)/29 | BO36: IMFT | BP36: =(0.0+SUM($B36:B36))/(306+1) | BQ36: =(0.0+SUM($B36:C36))/(306+2) | BR36: =(0.0+SUM($B36:D36))/(306+3) | BS36: =(0.0+SUM($B36:E36))/(306+4) | BT36: =(0.0+SUM($B36:F36))/(306+5) | BU36: =(0.0+SUM($B36:G36))/(306+6) | BV36: =(0.0+SUM($B36:H36))/(306+7) | BW36: =(0.0+SUM($B36:I36))/(306+8) | BX36: =(0.0+SUM($B36:J36))/(306+9) | BY36: =(0.0+SUM($B36:K36))/(306+10) | BZ36: =(0.0+SUM($B36:L36))/(306+11) | CA36: =(0.0+SUM($B36:M36))/(306+12) | CB36: =(0.0+SUM($B36:N36))/(306+13) | CC36: =(0.0+SUM($B36:O36))/(306+14) | CD36: =(0.0+SUM($B36:P36))/(306+15) | CE36: =(0.0+SUM($B36:Q36))/(306+16) | CF36: =(0.0+SUM($B36:R36))/(306+17) | CG36: =(0.0+SUM($B36:S36))/(306+18) | CH36: =(0.0+SUM($B36:T36))/(306+19) | CI36: =(0.0+SUM($B36:U36))/(306+20) | CJ36: =(0.0+SUM($B36:V36))/(306+21) | CK36: =(0.0+SUM($B36:W36))/(306+22) | CL36: =(0.0+SUM($B36:X36))/(306+23) | CM36: =(0.0+SUM($B36:Y36))/(306+24) | CN36: =(0.0+SUM($B36:Z36))/(306+25) | CO36: =(0.0+SUM($B36:AA36))/(306+26) | CP36: =(0.0+SUM($B36:AB36))/(306+27) | CQ36: =(0.0+SUM($B36:AC36))/(306+28) | CR36: =(0.0+SUM($B36:AD36))/(306+29) | CY36: IMFT | CZ36: 305.31707 | DA36: 307.08871 | DB36: 309.464 | DC36: 311.96825 | DD36: 313.62992 | DE36: 314.75 | DF36: 316.72093 | DG36: 319.13846 | DH36: 321.1145 | DI36: 323.37121 | DJ36: 325.58647 | DK36: 328.33582 | DL36: 330.3037 | DM36: 333.04412 | DN36: 335.25547 | DO36: 337.30435 | DP36: 340.23022 | DQ36: 343.22857 | DR36: 343.89362 | DS36: 345.96479 | DT36: 347.59441 | DU36: 349.92361 | DV36: 352.17241 | DW36: 354.68493 | DX36: 357.70748 | DY36: 359.5473 | DZ36: 362.83893 | EA36: 363.88667 | EB36: 366.62914 | EC36: 368.50658 | ED36: 371.18954
A37: POL | B37: 0 | C37: 0 | D37: 0 | E37: 0 | F37: 0 | G37: 0 | H37: 0 | I37: 0 | J37: 0 | K37: 0 | L37: 0 | M37: 0 | N37: 0 | O37: 0 | P37: 0 | Q37: 0 | R37: 0 | S37: 0 | T37: 0 | U37: 0 | V37: 0 | W37: 0 | X37: 0 | Y37: 0 | Z37: 0 | AA37: 0 | AB37: 0 | AC37: 0 | AD37: 0 | AH37: POL | AI37: =SUM($B37:B37)/1 | AJ37: =SUM($B37:C37)/2 | AK37: =SUM($B37:D37)/3 | AL37: =SUM($B37:E37)/4 | AM37: =SUM($B37:F37)/5 | AN37: =SUM($B37:G37)/6 | AO37: =SUM($B37:H37)/7 | AP37: =SUM($B37:I37)/8 | AQ37: =SUM($B37:J37)/9 | AR37: =SUM($B37:K37)/10 | AS37: =SUM($B37:L37)/11 | AT37: =SUM($B37:M37)/12 | AU37: =SUM($B37:N37)/13 | AV37: =SUM($B37:O37)/14 | AW37: =SUM($B37:P37)/15 | AX37: =SUM($B37:Q37)/16 | AY37: =SUM($B37:R37)/17 | AZ37: =SUM($B37:S37)/18 | BA37: =SUM($B37:T37)/19 | BB37: =SUM($B37:U37)/20 | BC37: =SUM($B37:V37)/21 | BD37: =SUM($B37:W37)/22 | BE37: =SUM($B37:X37)/23 | BF37: =SUM($B37:Y37)/24 | BG37: =SUM($B37:Z37)/25 | BH37: =SUM($B37:AA37)/26 | BI37: =SUM($B37:AB37)/27 | BJ37: =SUM($B37:AC37)/28 | BK37: =SUM($B37:AD37)/29 | BO37: POL | BP37: =(0.0+SUM($B37:B37))/(306+1) | BQ37: =(0.0+SUM($B37:C37))/(306+2) | BR37: =(0.0+SUM($B37:D37))/(306+3) | BS37: =(0.0+SUM($B37:E37))/(306+4) | BT37: =(0.0+SUM($B37:F37))/(306+5) | BU37: =(0.0+SUM($B37:G37))/(306+6) | BV37: =(0.0+SUM($B37:H37))/(306+7) | BW37: =(0.0+SUM($B37:I37))/(306+8) | BX37: =(0.0+SUM($B37:J37))/(306+9) | BY37: =(0.0+SUM($B37:K37))/(306+10) | BZ37: =(0.0+SUM($B37:L37))/(306+11) | CA37: =(0.0+SUM($B37:M37))/(306+12) | CB37: =(0.0+SUM($B37:N37))/(306+13) | CC37: =(0.0+SUM($B37:O37))/(306+14) | CD37: =(0.0+SUM($B37:P37))/(306+15) | CE37: =(0.0+SUM($B37:Q37))/(306+16) | CF37: =(0.0+SUM($B37:R37))/(306+17) | CG37: =(0.0+SUM($B37:S37))/(306+18) | CH37: =(0.0+SUM($B37:T37))/(306+19) | CI37: =(0.0+SUM($B37:U37))/(306+20) | CJ37: =(0.0+SUM($B37:V37))/(306+21) | CK37: =(0.0+SUM($B37:W37))/(306+22) | CL37: =(0.0+SUM($B37:X37))/(306+23) | CM37: =(0.0+SUM($B37:Y37))/(306+24) | CN37: =(0.0+SUM($B37:Z37))/(306+25) | CO37: =(0.0+SUM($B37:AA37))/(306+26) | CP37: =(0.0+SUM($B37:AB37))/(306+27) | CQ37: =(0.0+SUM($B37:AC37))/(306+28) | CR37: =(0.0+SUM($B37:AD37))/(306+29) | CY37: POL | CZ37: 642.00813 | DA37: 641.47581 | DB37: 640.176 | DC37: 642.11905 | DD37: 641.46457 | DE37: 641.82812 | DF37: 641.68217 | DG37: 641.42308 | DH37: 642.41221 | DI37: 642.37121 | DJ37: 642.03008 | DK37: 642.57463 | DL37: 642.02222 | DM37: 642.02941 | DN37: 641.07299 | DO37: 640.31884 | DP37: 638.84892 | DQ37: 637.71429 | DR37: 638.41844 | DS37: 637.88028 | DT37: 636.81119 | DU37: 635.54167 | DV37: 635.22069 | DW37: 634.82192 | DX37: 635.04082 | DY37: 633.98649 | DZ37: 633.48993 | EA37: 633.14667 | EB37: 633.02649 | EC37: 633.18421 | ED37: 632.76471
A38: SALT | B38: 0 | C38: 0 | D38: 0 | E38: 0 | F38: 0 | G38: 0 | H38: 0 | I38: 0 | J38: 0 | K38: 0 | L38: 0 | M38: 0 | N38: 0 | O38: 0 | P38: 0 | Q38: 0 | R38: 0 | S38: 0 | T38: 0 | U38: 0 | V38: 0 | W38: 0 | X38: 0 | Y38: 0 | Z38: 0 | AA38: 0 | AB38: 0 | AC38: 0 | AD38: 0 | AH38: SALT | AI38: =SUM($B38:B38)/1 | AJ38: =SUM($B38:C38)/2 | AK38: =SUM($B38:D38)/3 | AL38: =SUM($B38:E38)/4 | AM38: =SUM($B38:F38)/5 | AN38: =SUM($B38:G38)/6 | AO38: =SUM($B38:H38)/7 | AP38: =SUM($B38:I38)/8 | AQ38: =SUM($B38:J38)/9 | AR38: =SUM($B38:K38)/10 | AS38: =SUM($B38:L38)/11 | AT38: =SUM($B38:M38)/12 | AU38: =SUM($B38:N38)/13 | AV38: =SUM($B38:O38)/14 | AW38: =SUM($B38:P38)/15 | AX38: =SUM($B38:Q38)/16 | AY38: =SUM($B38:R38)/17 | AZ38: =SUM($B38:S38)/18 | BA38: =SUM($B38:T38)/19 | BB38: =SUM($B38:U38)/20 | BC38: =SUM($B38:V38)/21 | BD38: =SUM($B38:W38)/22 | BE38: =SUM($B38:X38)/23 | BF38: =SUM($B38:Y38)/24 | BG38: =SUM($B38:Z38)/25 | BH38: =SUM($B38:AA38)/26 | BI38: =SUM($B38:AB38)/27 | BJ38: =SUM($B38:AC38)/28 | BK38: =SUM($B38:AD38)/29 | BO38: SALT | BP38: =(0.0+SUM($B38:B38))/(306+1) | BQ38: =(0.0+SUM($B38:C38))/(306+2) | BR38: =(0.0+SUM($B38:D38))/(306+3) | BS38: =(0.0+SUM($B38:E38))/(306+4) | BT38: =(0.0+SUM($B38:F38))/(306+5) | BU38: =(0.0+SUM($B38:G38))/(306+6) | BV38: =(0.0+SUM($B38:H38))/(306+7) | BW38: =(0.0+SUM($B38:I38))/(306+8) | BX38: =(0.0+SUM($B38:J38))/(306+9) | BY38: =(0.0+SUM($B38:K38))/(306+10) | BZ38: =(0.0+SUM($B38:L38))/(306+11) | CA38: =(0.0+SUM($B38:M38))/(306+12) | CB38: =(0.0+SUM($B38:N38))/(306+13) | CC38: =(0.0+SUM($B38:O38))/(306+14) | CD38: =(0.0+SUM($B38:P38))/(306+15) | CE38: =(0.0+SUM($B38:Q38))/(306+16) | CF38: =(0.0+SUM($B38:R38))/(306+17) | CG38: =(0.0+SUM($B38:S38))/(306+18) | CH38: =(0.0+SUM($B38:T38))/(306+19) | CI38: =(0.0+SUM($B38:U38))/(306+20) | CJ38: =(0.0+SUM($B38:V38))/(306+21) | CK38: =(0.0+SUM($B38:W38))/(306+22) | CL38: =(0.0+SUM($B38:X38))/(306+23) | CM38: =(0.0+SUM($B38:Y38))/(306+24) | CN38: =(0.0+SUM($B38:Z38))/(306+25) | CO38: =(0.0+SUM($B38:AA38))/(306+26) | CP38: =(0.0+SUM($B38:AB38))/(306+27) | CQ38: =(0.0+SUM($B38:AC38))/(306+28) | CR38: =(0.0+SUM($B38:AD38))/(306+29) | CY38: SALT | CZ38: 387.07317 | DA38: 387.8871 | DB38: 389.592 | DC38: 389.9127 | DD38: 389.66929 | DE38: 390.5625 | DF38: 390.99225 | DG38: 391.71538 | DH38: 392.53435 | DI38: 393.75 | DJ38: 394.5188 | DK38: 395.20149 | DL38: 396.12593 | DM38: 396.74265 | DN38: 396.37956 | DO38: 394.50725 | DP38: 393.69784 | DQ38: 395.40714 | DR38: 394.31915 | DS38: 395.64789 | DT38: 396.14685 | DU38: 395.625 | DV38: 394.45517 | DW38: 395.26712 | DX38: 394.86395 | DY38: 394.65541 | DZ38: 394.85906 | EA38: 394.74667 | EB38: 395.87417 | EC38: 395.64474 | ED38: 396.17647
